Workbook

Sheet README
A1: Carvana（CVNA）個股模型 v0.3.2（2026-10-29）— 命題＋營收線＋收支平衡＋信用風險
A2: 命題：Carvana 的高成長與獲利，毛利約三成、調整後 EBITDA 約一半來自「把車貸賣掉的利得」；只要消費信用與 ABS 市場正常，它能自我融資，一旦信用循環轉向，利得、放款與台數會同時被壓縮——問題是它的現金與債務結構撐不撐得住
A3: 核心問題：在信用循環轉差時，Carvana 能否不靠新股與新債維持收支平衡？債務／EBITDA 會不會越過評等門檻？
A4: 重點觀察（數字取自本活頁簿）
A5: ="① 收支：情境 B 的 FY2027–FY2031 收支關卡合計 "&TEXT(CF!D4,"#,##0")&"（百萬美元），情境 C 為 "&TEXT(CF!E4,"#,##0")&"；情境 C 期間最低現金 "&TEXT(CF!E6,"#,##0")&"，新增外部融資需求 "&TEXT(CF!E5,"#,##0")&"。" -> ① 收支：情境 B 的 FY2027–FY2031 收支關卡合計 16,038（百萬美元），情境 C 為 5,947；情境 C 期間最低現金 4,225，新增外部融資需求 0。
A6: ="② 債信：2026-09-30 TTM 債務／EBITDA "&TEXT(ttm_lev,"0.0")&"x，扣除貸款出售利得後為 "&TEXT(ttm_lev_xg,"0.0")&"x；情境 C 2027 年債務／EBITDA "&TEXT(Credit!E47,"0.0")&"x（Moody's 升評門檻 4.0x）。" -> ② 債信：2026-09-30 TTM 債務／EBITDA 1.9x，扣除貸款出售利得後為 3.9x；情境 C 2027 年債務／EBITDA 3.8x（Moody's 升評門檻 4.0x）。
A7: ="③ 貸款去化：已承諾承購（Ally＋整批出售）只涵蓋情境 B 2027 年發放量的 "&TEXT(Credit!E37,"0%")&"；若所有買方與 ABS 同時停止，現金與倉儲額度約可撐 "&TEXT(Credit!C92,"0.0")&" 個月（Ally 照常則 "&TEXT(Credit!D92,"0.0")&" 個月）。" -> ③ 貸款去化：已承諾承購（Ally＋整批出售）只涵蓋情境 B 2027 年發放量的 59%；若所有買方與 ABS 同時停止，現金與倉儲額度約可撐 3.7 個月（Ally 照常則 6.3 個月）。
A8: ="④ 消費信用：管理組合年化淨沖銷率 2026 上半年 "&TEXT(Credit!I66,"0.00%")&"（非 Prime 推得 "&TEXT(Credit!I68,"0.0%")&"），以一年前餘額計為 "&TEXT(Credit!I69,"0.00%")&"——改善有一部分來自組合快速成長的分母稀釋。" -> ④ 消費信用：管理組合年化淨沖銷率 2026 上半年 3.16%（非 Prime 推得 6.0%），以一年前餘額計為 4.10%——改善有一部分來自組合快速成長的分母稀釋。
A9: ="⑤ 估值：加權目標價 "&TEXT(v_tp_w,"0.0")&" 美元，相對現價 "&TEXT(v_up,"+0%;-0%")&"（"&Val!C94&"）；市場隱含 2030 年須有約 "&TEXT(Val!C93/10000,"0")&" 萬台零售量（以情境 B 每台 EBITDA 換算；情境 B 為 "&TEXT(Thesis!H34/10000,"0")&" 萬台）。三情境 IRR 機率加權 "&TEXT(v_irr_w,"0.0%")&"，低於 WACC "&TEXT(v_wacc,"0.0%")&"——結論取決於折現率。" -> ⑤ 估值：加權目標價 35.6 美元，相對現價 -44%（放空）；市場隱含 2030 年須有約 218 萬台零售量（以情境 B 每台 EBITDA 換算；情境 B 為 163 萬台）。三情境 IRR 機率加權 12.7%，低於 WACC 17.7%——結論取決於折現率。
A11: 工作表：README → In（輸入）→ Q（事實總帳）→ Thesis（命題：台數 × 單位經濟）→ PL（營收線 → 損益）→ CF（收支模組、債務表）→ Credit（信用風險七節）→ Val（DCF＋倍數）→ Recon（對帳）→ Sens（敏感度）→ Sources
A12: 會計年度＝曆年；金額百萬美元；每台金額美元。FY2026E＝前三季實績＋第四季模型（v0.2 起）；公司自 Q4 2026 起不再提供季度與年度指引，2027 年起改以 GAAP 指標（中期目標：300 萬台、營業利益率 12.5%，2030–2035）
A13: 營收分部層：Carvana 只有一個應報導部門（10-Q 附註 2）；營收列採公司固定揭露的三條營收線（零售、批發、其他），其他營收下拆「貸款出售利得」與「非貸款」兩個命題子列，PL 頁核對列為 0
A14: 與專案既有模型的關係：比照 company-models 的 Oracle v0.4（命題＋分部架構、五級評等、DCF 50%＋倍數 50%、rf 5.00%）與 CoreWeave 收支模型「Backlog 不是現金」的收支精神；本模型不讀 Tokenomics（Carvana 與算力無關）
A15: v0.1 → v0.2（2026-10-29）：納入 Q3 2026 實績（台數 217,385，高於共識 3.4%；零售 GPU 3,556 高於共識、批發 GPU 708 低於共識、其他 GPU 2,733 持平；SG&A 805 偏高）；2026 年改為前三季實績＋Q4 模型；債務表改為實際（定期貸款 B 1,660 以利率交換固定 4.055% 至 2028-07、2030 年票據已以溢價 50 贖回、車隊融資 142）；SG&A 變動成本 2,700 → 2,900；出售貸款存續期間 1.8 → 2.0（貸款池模擬）；現價改為 2026-10-28 盤後 63.99（v0.2.1，Andy 指定）；TTM 改為 Q4 2025–Q3 2026。v0.3（2026-10-29，Andy 選項 ③）：對 Q3 利多與利空對稱處理——SG&A 變動成本 2,900 → 2,800、情境 B 零售 GPU 2027 年 3,350 → 3,450、長期 3,300 → 3,350。v0.3.1：情境 C 存貨天數改為兩年路徑（2027 年 70、2028 年 65、2029 年起 60；原為 2027 年 75、2028 年即回 60）
A16: 已知限制
A17: 1. 非 Prime（144A）證券化的靜態池損失未公開，非 Prime 淨沖銷率以「全部 − Prime」推得。2. 利息以期初餘額計，忽略年內再融資時點（再融資年度另以月數拆）。3. TRA 以平均攤付處理，未隨課稅所得與未來交換變動。4. 產能建置成本、維護資本支出、利得率對損失與利差的傳導係數皆為 Assumed。5. 估值折現基準點為 2026 年底，未計 2026 年第四季現金流。6. 關係人與放空報告主張無法以公開資料驗證，只列對照。7. 2026 年評等動作未找到，門檻沿用 2025 年公開說法。

Sheet In
A1: In — 輸入（藍字＝輸入；黑字＝公式；基準欄 E，低 D、高 F）。金額：百萬美元（US$M）；每台金額：美元；台數：輛
A2: 標記：Verified／Interested-party／Analogy／Assumed／Derived；Analogy、Assumed 給低／高區間。公司財報數字依專案慣例標 Interested-party（公司自述、經會計師核閱或查核）
A3: 鍵 | B3: 項目 | C3: 單位 | D3: 低 | E3: 基準 | F3: 高 | G3: 標記 | H3: 來源1 | I3: 來源2／說明
A4: A. 股價、股數
A5: px | B5: 現價（2026-10-28 盤後） | C5: US$ | E5: 63.99 | G5: Interested-party | H5: StockStory（2026-10-28）：Q3 財報公布後盤後上漲 8.4% 至 63.99 | I5: Andy 2026-10-29 指定用盤後價；推得收盤約 59.03；2026-10-26 收盤 56.61（stockanalysis）
A6: sh_fx | B6: 完全轉換股數（LLC 單位全數交換＋其他稀釋） | C6: 百萬股 | E6: 1127 | G6: Interested-party | H6: Carvana Q2 2026 股東信（8-K 2026-07-29 附件 99.1） 第 1 頁：Assuming full conversion … 1.127 billion shares | I6: A 類流通 719.0 百萬股＋B 類 380.5 百萬股（B 類為表決權股；經濟權益以 LLC 單位交換計）
A7: B. 命題：零售台數路徑
A8: u_q4 | B8: 2026Q4 零售台數 | C8: 輛 | E8: =lq_units*(1+q4_seq) -> 221732.7 | G8: Derived | H8: Q3 2026 實績 217,385 ×（1＋季增） | I8: 公司指引 Q4 較 Q3 增加（Q3 2026 股東信）
A9: q4_adj | B9: 2026Q4 每台總毛利季節性調整（相對 Q3） | C9: US$ | D9: -935 | E9: -600 | F9: -300 | G9: Derived | H9: Q4 2025 總 GPU 6,427 較 Q3 2025 7,362 低 935（零售 −466、其他 −233、批發 −236；Q 頁） | I9: 季節性；以零售毛利承載
A10: q4_seq | B10: 2026Q4 台數相對 Q3 變化 | C10: % | D10: 0 | E10: 0.02 | F10: 0.05 | G10: Assumed | H10: 公司指引：sequential increase（Q3 2026 股東信）；2025 Q4／Q3＝+4.9% | I10: —
A11: g27_A | B11: 情境 A：2027 年零售台數年增 | C11: % | D11: 0.24 | E11: 0.32 | F11: 0.4 | G11: Assumed | H11: 公司目標 2030–2035 年 300 萬台（股東信）；此路徑約 2033 年觸及用地上限 | I11: —
A12: g28_A | B12: 情境 A：2028 年零售台數年增 | C12: % | D12: 0.2 | E12: 0.28 | F12: 0.36 | G12: Assumed | H12: 同上 | I12: —
A13: g30_A | B13: 情境 A：2030 年零售台數年增（2029 年取 2028 與 2030 中點） | C13: % | D13: 0.15 | E13: 0.2 | F13: 0.25 | G13: Assumed | H13: 同上 | I13: —
A14: g35_A | B14: 情境 A：2035 年零售台數年增（2031–2034 線性） | C14: % | D14: 0.05 | E14: 0.08 | F14: 0.11 | G14: Assumed | H14: 同上 | I14: —
A15: g27_B | B15: 情境 B：2027 年零售台數年增 | C15: % | D15: 0.17 | E15: 0.25 | F15: 0.33 | G15: Assumed | H15: 2025 年 +43%、2026 上半年 +39%、Q3 共識 +35%，逐年放緩；2035 年約為二手零售市場 6% | I15: —
A16: g28_B | B16: 情境 B：2028 年零售台數年增 | C16: % | D16: 0.12 | E16: 0.2 | F16: 0.28 | G16: Assumed | H16: 同上 | I16: —
A17: g30_B | B17: 情境 B：2030 年零售台數年增（2029 年取 2028 與 2030 中點） | C17: % | D17: 0.08 | E17: 0.13 | F17: 0.18 | G17: Assumed | H17: 同上 | I17: —
A18: g35_B | B18: 情境 B：2035 年零售台數年增（2031–2034 線性） | C18: % | D18: 0.02 | E18: 0.05 | F18: 0.08 | G18: Assumed | H18: 同上 | I18: —
A19: g27_C | B19: 情境 C：2027 年零售台數年增 | C19: % | D19: -0.18 | E19: -0.1 | F19: -0.02 | G19: Assumed | H19: 2027 年次級車貸循環：放款收緊、二手車價下跌，台數 −10%；2028 年起緩步恢復 | I19: —
A20: g28_C | B20: 情境 C：2028 年零售台數年增 | C20: % | D20: -0.03 | E20: 0.05 | F20: 0.13 | G20: Assumed | H20: 同上 | I20: —
... A22: g35_C | B22: 情境 C：2035 年零售台數年增（2031–2034 線性） | C22: % | D22: 0.01 | E22: 0.04 | F22: 0.07 | G22: Assumed | H22: 同上 | I22: —
A23: unit_cap | B23: 生產用地可支援的年零售台數上限 | C23: 輛 | E23: 3000000 | G23: Interested-party | H23: Carvana Q2 2026 股東信（8-K 2026-07-29 附件 99.1） 第 3 頁：real estate to support annual retail production of 3 million | I23: 台數路徑以此為上限
A24: cap_0 | B24: 已完成建置的年產能（2026 年中） | C24: 輛 | E24: 1500000 | G24: Interested-party | H24: Carvana Q2 2026 股東信（8-K 2026-07-29 附件 99.1） 第 3 頁：fully built out annual capacity for approximately 1.5 million | I24: —
A25: util | B25: 產能利用率上限（超過即需擴建） | C25: % | D25: 0.75 | E25: 0.85 | F25: 0.95 | G25: Assumed | H25: 公司未揭露（未找到） | I25: —
A26: capcost | B26: 每台年產能建置成本 | C26: US$／台 | D26: 400 | E26: 600 | F26: 1000 | G26: Assumed | H26: ADESA 站點全面改建成本：未找到（公司只揭露首個全面改建 2027 年初投產） | I26: 成長性資本支出＝新增產能 × 每台成本
A27: C. 命題：單位經濟（每零售台）
A28: asp_q4 | B28: 2026Q4 零售每台營收 | C28: US$ | D28: 27500 | E28: 28263 | F28: 28800 | G28: Interested-party | H28: Carvana Q3 2026 股東信（8-K 2026-10-28 附件 99.1）：Q3 2026 零售每台營收 28,263 | I28: —
A29: asp_g | B29: 零售每台售價年增（2027 起） | C29: % | D29: 0 | E29: 0.02 | F29: 0.04 | G29: Assumed | H29: 二手車價（Manheim 指數 2026-09 為 205.9，年減 0.6%，Cox Automotive） | I29: 貸款發放額、批發營收同幅
A30: whs_pu | B30: 批發營收 ÷ 零售台數（2026Q4 起） | C30: US$ | E30: =Q!K7*1000000/Q!K4 -> 6183.3274 | G30: Derived | H30: 2026 前三季批發營收 3,723 ÷ 零售 602,103 台（Q 頁） | I30: Q3 單季 5,989
A31: gpr_q4 | B31: 2026Q4 零售毛利／台（季節調整前） | C31: US$ | D31: 3165 | E31: 3556 | F31: 3600 | G31: Interested-party | H31: Carvana Q3 2026 股東信（8-K 2026-10-28 附件 99.1）：Q3 2026 零售 GPU 3,556（共識 3,404） | I31: 低＝Q1 2026 實績
A32: gpr27_A | B32: 情境 A：2027 年零售 GPU | C32: US$ | D32: 3300 | E32: 3600 | F32: 3900 | G32: Assumed | H32: 2024 年 3,312、2025 年 3,315、2026 前三季 3,431、Q3 3,556（共識 3,404） | I32: 2028–2029 線性收斂至長期值
A33: gprLT_A | B33: 情境 A：2030 年起零售 GPU | C33: US$ | D33: 3400 | E33: 3700 | F33: 4000 | G33: Assumed | H33: 同上 | I33: —
A34: gpr27_B | B34: 情境 B：2027 年零售 GPU | C34: US$ | D34: 3150 | E34: 3450 | F34: 3750 | G34: Assumed | H34: 2024 年 3,312、2025 年 3,315、2026 前三季 3,431、Q3 3,556（共識 3,404）；情境 B：Q3 利多延續一半（Andy 2026-10-29 選項 ③；v0.2 為 2027 年 3,350、長期 3,300） | I34: 2028–2029 線性收斂至長期值
A35: gprLT_B | B35: 情境 B：2030 年起零售 GPU | C35: US$ | D35: 3050 | E35: 3350 | F35: 3650 | G35: Assumed | H35: 同上 | I35: —
A36: gpr27_C | B36: 情境 C：2027 年零售 GPU | C36: US$ | D36: 2400 | E36: 2700 | F36: 3000 | G36: Assumed | H36: 2024 年 3,312、2025 年 3,315、2026 前三季 3,431、Q3 3,556（共識 3,404）；情境 C：二手車價下跌時零售毛利受壓（2022 年循環曾大幅下滑） | I36: 2028–2029 線性收斂至長期值
A37: gprLT_C | B37: 情境 C：2030 年起零售 GPU | C37: US$ | D37: 2800 | E37: 3100 | F37: 3400 | G37: Assumed | H37: 同上 | I37: —
A38: gpw_h2 | B38: 2026Q4 起批發毛利／零售台 | C38: US$ | D38: 650 | E38: 708 | F38: 806 | G38: Interested-party | H38: Carvana Q3 2026 股東信（8-K 2026-10-28 附件 99.1）：Q3 2026 批發 GPU 708（共識 812） | I38: 高＝2026 上半年 806
A39: gpw27_C | B39: 情境 C：2027 年批發毛利／零售台 | C39: US$ | D39: 550 | E39: 650 | F39: 750 | G39: Assumed | H39: 批發車價下跌時批發毛利下降 | I39: 情境 A、B 沿用 gpw_h2
A40: opu | B40: 每零售台貸款發放金額（2026Q4） | C40: US$ | E40: =Q!J16*1000000/Q!J4 -> 23837.891 | G40: Derived | H40: Q3 2026 發放 5,182（前三季 14,187 − 上半年 9,005）÷ 217,385 台（Q 頁） | I40: 2027 起隨售價年增
A41: gos_h2 | B41: 2026Q4 貸款出售利得率（利得 ÷ 發放額） | C41: % | D41: 0.065 | E41: =Q!J17/Q!J16 -> 0.073523736 | F41: 0.08 | G41: Derived | H41: Q3 2026 利得 381（前三季 1,084 − 上半年 703）÷ 發放 5,182（Q 頁） | I41: Q2 2026 7.35%；公司稱 Q3 受基準利率快速上升與油價影響每台約 −200
...

Sheet Q
A1: Q — 事實總帳（US$M；台數為輛）。來源：各季股東信（8-K 附件 99.1）、10-Q、10-K、SEC XBRL；carvana/data/carvana_facts_20261029.json
A2: 欄：C–J＝Q4'24、Q1'25、Q2'25、Q3'25、Q4'25、Q1'26、Q2'26、Q3'26；K＝2026 前三季；L＝FY2024；M＝FY2025。核對列應為 0
A3: 項目 | B3: 單位 | C3: Q4'24 | D3: Q1'25 | E3: Q2'25 | F3: Q3'25 | G3: Q4'25 | H3: Q1'26 | I3: Q2'26 | J3: Q3'26 | K3: 2026 前三季 | L3: FY2024 | M3: FY2025
A4: 零售台數 | B4: 輛 | C4: 114379 | D4: 133898 | E4: 143280 | F4: 155941 | G4: 163522 | H4: 187393 | I4: 197325 | J4: 217385 | K4: 602103 | L4: 416348 | M4: 596641
A5: 批發台數 | B5: 輛 | C5: 48770 | D5: 63454 | E5: 72770 | F5: 80369 | G5: 81050 | H5: 83574 | I5: 105052 | J5: 111119 | K5: 299745 | L5: 199780 | M5: 297643
A6: 零售車輛銷售 | B6: US$M | C6: 2552 | D6: 2980 | E6: 3405 | F6: 3996 | G6: 4156 | H6: 4828 | I6: 5507 | J6: 6144 | K6: 16479 | L6: 9681 | M6: 14537
A7: 批發銷售與營收 | B7: US$M | C7: 678 | D7: 863 | E7: 1024 | F7: 1177 | G7: 988 | H7: 1078 | I7: 1343 | J7: 1302 | K7: 3723 | L7: 2841 | M7: 4052
A8: 其他銷售與營收 | B8: US$M | C8: 317 | D8: 389 | E8: 411 | F8: 474 | G8: 459 | H8: 526 | I8: 526 | J8: 594 | K8: 1646 | L8: 1151 | M8: 1733
A9: 合併營收 | B9: US$M | C9: 3547 | D9: 4232 | E9: 4840 | F9: 5647 | G9: 5603 | H9: 6432 | I9: 7376 | J9: 8040 | K9: 21848 | L9: 13673 | M9: 20322
A10: 零售毛利 | B10: US$M | C10: 369 | D10: 429 | E10: 521 | F10: 539 | G10: 489 | H10: 593 | I10: 700 | J10: 773 | K10: 2066 | L10: 1379 | M10: 1978
A11: 批發毛利 | B11: US$M | C11: 77 | D11: 111 | E11: 132 | F11: 135 | G11: 103 | H11: 152 | I11: 158 | J11: 154 | K11: 464 | L11: 346 | M11: 481
A12: SG&A | B12: US$M | C12: 494 | D12: 535 | E12: 551 | F12: 595 | G12: 627 | H12: 690 | I12: 704 | J12: 805 | K12: 2199 | L12: 1874 | M12: 2308
A13: 營業利益 | B13: US$M | C13: 260 | D13: 394 | E13: 511 | F13: 552 | G13: 424 | H13: 581 | I13: 680 | J13: 714 | K13: 1975 | L13: 990 | M13: 1881
A14: 折舊攤銷（銷貨成本＋SG&A） | B14: US$M | C14: 74 | D14: 73 | E14: 68 | F14: 65 | G14: 69 | H14: 69 | I14: 69 | J14: 64 | K14: 202 | L14: 305 | M14: 275
A15: 股份基礎給付 | B15: US$M | C15: 21 | D15: 26 | E15: 26 | F15: 24 | G15: 23 | H15: 27 | I15: 26 | J15: 25 | K15: 78 | L15: 92 | M15: 99
... A20: 利息費用（淨） | B20: US$M | C20: 148 | D20: 139 | E20: 143 | F20: 125 | G20: 98 | H20: 99 | I20: 101 | J20: 98 | K20: 298 | L20: 651 | M20: 505
A21: 其他費用（收益）與清償損失（推得） | B21: US$M | C21: =C13-C20-C22-C23 -> -44 | D21: =D13-D20-D22-D23 -> -120 | E21: =E13-E20-E22-E23 -> 60 | F21: =F13-F20-F22-F23 -> 168 | G21: =G13-G20-G22-G23 -> 2158 | H21: =H13-H20-H22-H23 -> 41 | I21: =I13-I20-I22-I23 -> 0 | J21: =J13-J20-J22-J23 -> 64 | ... M21: =M13-M20-M22-M23 -> 2266
A22: 所得稅（利益） | B22: US$M | C22: -3 | D22: 2 | E22: 0 | F22: -4 | G22: -2783 | H22: 36 | I22: 66 | J22: 69 | K22: 171 | L22: -4 | M22: -2785
A23: 淨利（合併） | B23: US$M | C23: 159 | D23: 373 | E23: 308 | F23: 263 | G23: 951 | H23: 405 | I23: 513 | J23: 483 | K23: 1401 | L23: 404 | M23: 1895
A24: 其他營收中關係人部分（DriveTime 等） | B24: US$M | C24: 59 | D24: 72 | E24: 83 | F24: 93 | G24: 99 | H24: 114 | I24: 117 | J24: 129 | K24: 360 | L24: 200 | M24: 347
A25: 資本支出 | B25: US$M | C25: 24 | D25: 27 | E25: 31 | F25: 38 | G25: 51 | H25: 51 | I25: 51 | J25: 64 | K25: 166 | L25: 91 | M25: 147
A26: 營業活動現金流 | B26: US$M | C26: 60 | D26: 232 | E26: 29 | F26: 345 | G26: 430 | H26: 107 | I26: 238 | J26: 555 | K26: 900 | L26: 918 | M26: 1036
A27: 現金（期末） | B27: US$M | C27: 1716 | D27: 1858 | E27: 1857 | F27: 2142 | G27: 2327 | H27: 2410 | I27: 2630 | J27: 3049 | K27: 3049 | L27: 1716 | M27: 2327
A28: 存貨（期末） | B28: US$M | C28: 1608 | D28: 1503 | E28: 2023 | F28: 2316 | G28: 2408 | H28: 2664 | I28: 3263 | J28: 3456 | K28: 3456 | L28: 1608 | M28: 2408
A29: 待售貸款（期末） | B29: US$M | C29: 612 | D29: 737 | E29: 767 | F29: 724 | G29: 813 | H29: 982 | I29: 921 | J29: 896 | K29: 896 | L29: 612 | M29: 813
A30: 證券化受益權（期末） | B30: US$M | C30: 464 | D30: 475 | E30: 466 | F30: 486 | G30: 486 | H30: 492 | I30: 502 | J30: 557 | K30: 557 | L30: 464 | M30: 486
A31: 債務合計（含融資租賃，期末） | B31: US$M | C31: 5632 | D31: 5641 | E31: 5707 | F31: 5203 | G31: 5115 | H31: 5154 | I31: 5236 | J31: 5228 | K31: 5228 | L31: 5632 | M31: 5115
A32: 股東權益（含非控制權益，期末） | B32: US$M | C32: 1375 | D32: 1773 | E32: 2117 | F32: 2951 | G32: 4203 | H32: 4632 | I32: 5138 | J32: 5653 | K32: 5653 | L32: 1375 | M32: 4203
A33: 公司口徑總流動性資源（期末） | B33: US$M | C33: 5690 | D33: 5861 | E33: 5981 | F33: 6438 | G33: 6739 | H33: 6910 | I33: 7024 | J33: 7503 | K33: 7503 | L33: 5690 | M33: 6739
A34: 其他毛利（＝其他營收） | B34: US$M | C34: =C8 -> 317 | D34: =D8 -> 389 | E34: =E8 -> 411 | F34: =F8 -> 474 | G34: =G8 -> 459 | H34: =H8 -> 526 | I34: =I8 -> 526 | J34: =J8 -> 594 | ... M34: =M8 -> 1733
A35: 毛利合計 | B35: US$M | C35: =C10+C11+C34 -> 763 | D35: =D10+D11+D34 -> 929 | E35: =E10+E11+E34 -> 1064 | F35: =F10+F11+F34 -> 1148 | G35: =G10+G11+G34 -> 1051 | H35: =H10+H11+H34 -> 1271 | I35: =I10+I11+I34 -> 1384 | J35: =J10+J11+J34 -> 1521 | ... M35: =M10+M11+M34 -> 4192
A36: 核對：營收線合計 − 合併營收 | B36: US$M | C36: =C6+C7+C8-C9 -> 0 | D36: =D6+D7+D8-D9 -> 0 | E36: =E6+E7+E8-E9 -> 0 | F36: =F6+F7+F8-F9 -> 0 | G36: =G6+G7+G8-G9 -> 0 | H36: =H6+H7+H8-H9 -> 0 | I36: =I6+I7+I8-I9 -> 0 | J36: =J6+J7+J8-J9 -> 0 | ... M36: =M6+M7+M8-M9 -> 0
A37: 核對：營業利益＋其他營業費用＋折舊＋SBC − 權證 − 調整後 EBITDA | B37: US$M | C37: =C13+C38+C14+C15-C18-C19 -> 0 | D37: =D13+D38+D14+D15-D18-D19 -> 0 | E37: =E13+E38+E14+E15-E18-E19 -> 0 | F37: =F13+F38+F14+F15-F18-F19 -> 0 | G37: =G13+G38+G14+G15-G18-G19 -> 0 | H37: =H13+H38+H14+H15-H18-H19 -> 0 | I37: =I13+I38+I14+I15-I18-I19 -> 0 | J37: =J13+J38+J14+J15-J18-J19 -> 0 | ... M37: =M13+M38+M14+M15-M18-M19 -> 0
A38: 其他營業費用（推得） | B38: US$M | C38: =C35-C12-C13 -> 9 | D38: =D35-D12-D13 -> 0 | E38: =E35-E12-E13 -> 2 | F38: =F35-F12-F13 -> 1 | G38: =G35-G12-G13 -> 0 | H38: =H35-H12-H13 -> 0 | I38: =I35-I12-I13 -> 0 | J38: =J35-J12-J13 -> 2 | ... M38: =M35-M12-M13 -> 3
A39: 貸款出售利得率 | B39: % | C39: =IF(C16>0,C17/C16,"") -> 0.093942054 | D39: =IF(D16>0,D17/D16,"") -> 0.10263158 | E39: =IF(E16>0,E17/E16,"") -> 0.088788075 | F39: =IF(F16>0,F17/F16,"") -> 0.096389051 | G39: =IF(G16>0,G17/G16,"") -> 0.086848635 | H39: =IF(H16>0,H17/H16,"") -> 0.083215797 | I39: =IF(I16>0,I17/I16,"") -> 0.073458219 | J39: =IF(J16>0,J17/J16,"") -> 0.073523736 | ... M39: =IF(M16>0,M17/M16,"") -> 0.093152182
A40: 總毛利／零售台 | B40: US$ | C40: =C35*1000000/C4 -> 6670.805 | D40: =D35*1000000/D4 -> 6938.1171 | E40: =E35*1000000/E4 -> 7426.019 | F40: =F35*1000000/F4 -> 7361.7586 | G40: =G35*1000000/G4 -> 6427.2697 | H40: =H35*1000000/H4 -> 6782.5372 | I40: =I35*1000000/I4 -> 7013.8097 | J40: =J35*1000000/J4 -> 6996.8029 | ... M40: =M35*1000000/M4 -> 7026.0006
A41: 零售毛利／台 | B41: US$ | C41: =C10*1000000/C4 -> 3226.1167 | D41: =D10*1000000/D4 -> 3203.9314 | E41: =E10*1000000/E4 -> 3636.2367 | F41: =F10*1000000/F4 -> 3456.4354 | G41: =G10*1000000/G4 -> 2990.4233 | H41: =H10*1000000/H4 -> 3164.4725 | I41: =I10*1000000/I4 -> 3547.4471 | J41: =J10*1000000/J4 -> 3555.9031 | ... M41: =M10*1000000/M4 -> 3315.2264
A42: 其他毛利／台 | B42: US$ | C42: =C34*1000000/C4 -> 2771.4878 | D42: =D34*1000000/D4 -> 2905.1965 | E42: =E34*1000000/E4 -> 2868.5092 | F42: =F34*1000000/F4 -> 3039.6111 | G42: =G34*1000000/G4 -> 2806.9618 | H42: =H34*1000000/H4 -> 2806.9352 | I42: =I34*1000000/I4 -> 2665.6531 | J42: =J34*1000000/J4 -> 2732.4792 | ... M42: =M34*1000000/M4 -> 2904.5942
A43: SG&A／台 | B43: US$ | C43: =C12*1000000/C4 -> 4318.9746 | D43: =D12*1000000/D4 -> 3995.5787 | E43: =E12*1000000/E4 -> 3845.617 | F43: =F12*1000000/F4 -> 3815.5456 | G43: =G12*1000000/G4 -> 3834.3464 | H43: =H12*1000000/H4 -> 3682.1013 | I43: =I12*1000000/I4 -> 3567.7182 | J43: =J12*1000000/J4 -> 3703.1074 | ... M43: =M12*1000000/M4 -> 3868.3228
A44: 調整後 EBITDA 率 | B44: % | C44: =C19/C9 -> 0.10121229 | D44: =D19/D9 -> 0.11531191 | E44: =E19/E9 -> 0.12417355 | F44: =F19/F9 -> 0.11280326 | G44: =G19/G9 -> 0.091201142 | H44: =H19/H9 -> 0.10447761 | I44: =I19/I9 -> 0.10425705 | J44: =J19/J9 -> 0.099502488 | ... M44: =M19/M9 -> 0.11007775
...

Sheet Thesis
A1: Thesis — 命題模組：零售台數 × 每台單位經濟。其他毛利拆成「貸款出售利得＝每台發放額 × 利得率」與「非貸款部分（VSC、GAP 等）」；2026 年＝上半年實績＋下半年模型
A2: 讀法：Carvana 的利潤約三到四成來自把車貸賣掉的利得；賣得掉、賣得好，取決於消費信用表現與 ABS 市場。情境 C 的利得率由 Credit 頁 S2 的損失與利差假設推導
A4: 情境 A（樂觀：沿公司 300 萬台路徑、利得率維持）
A5: 項目 | B5: 單位 | C5: FY2025A | D5: FY2026E | E5: FY2027E | F5: FY2028E | G5: FY2029E | H5: FY2030E | I5: FY2031E | J5: FY2032E | K5: FY2033E | L5: FY2034E | M5: FY2035E
A6: 零售台數年增（2027 起為輸入；觸及上限後實際年增較低） | B6: % | C6: =Q!M4/Q!L4-1 -> 0.43303438 | D6: =D7/C7-1 -> 0.38078962 | E6: =g27_A -> 0.32 | F6: =g28_A -> 0.28 | G6: =(g28_A+g30_A)/2 -> 0.24 | H6: =g30_A -> 0.2 | I6: =g30_A+(g35_A-g30_A)*1/5 -> 0.176 | J6: =g30_A+(g35_A-g30_A)*2/5 -> 0.152 | K6: =g30_A+(g35_A-g30_A)*3/5 -> 0.128 | L6: =g30_A+(g35_A-g30_A)*4/5 -> 0.104 | M6: =g30_A+(g35_A-g30_A)*5/5 -> 0.08
A7: 零售台數 | B7: 輛 | C7: =fy25_units -> 596641 | D7: =ytd_units+u_q4 -> 823835.7 | E7: =MIN(D7*(1+E6),unit_cap) -> 1087463.1 | F7: =MIN(E7*(1+F6),unit_cap) -> 1391952.8 | G7: =MIN(F7*(1+G6),unit_cap) -> 1726021.5 | H7: =MIN(G7*(1+H6),unit_cap) -> 2071225.8 | I7: =MIN(H7*(1+I6),unit_cap) -> 2435761.5 | J7: =MIN(I7*(1+J6),unit_cap) -> 2805997.2 | K7: =MIN(J7*(1+K6),unit_cap) -> 3000000 | L7: =MIN(K7*(1+L6),unit_cap) -> 3000000 | M7: =MIN(L7*(1+M6),unit_cap) -> 3000000
A8: 零售每台營收 | B8: US$ | C8: =fy25_rev_ret*1000000/C7 -> 24364.735 | D8: =(ytd_rev_ret*1000000+(D7-ytd_units)*asp_q4)/D7 -> 27609.669 | E8: =D8*(1+asp_g) -> 28161.863 | F8: =E8*(1+asp_g) -> 28725.1 | G8: =F8*(1+asp_g) -> 29299.602 | H8: =G8*(1+asp_g) -> 29885.594 | I8: =H8*(1+asp_g) -> 30483.306 | J8: =I8*(1+asp_g) -> 31092.972 | K8: =J8*(1+asp_g) -> 31714.832 | L8: =K8*(1+asp_g) -> 32349.128 | M8: =L8*(1+asp_g) -> 32996.111
A9: 零售車輛銷售 | B9: US$M | C9: =C7*C8/1000000 -> 14537 | D9: =D7*D8/1000000 -> 22745.831 | E9: =E7*E8/1000000 -> 30624.987 | F9: =F7*F8/1000000 -> 39983.983 | G9: =G7*G8/1000000 -> 50571.742 | H9: =H7*H8/1000000 -> 61899.812 | I9: =I7*I8/1000000 -> 74250.063 | J9: =J7*J8/1000000 -> 87246.794 | ... M9: =M7*M8/1000000 -> 98988.332
A10: 批發營收／零售台 | B10: US$ | C10: =fy25_rev_whs*1000000/C7 -> 6791.3536 | D10: =(ytd_rev_whs*1000000+(D7-ytd_units)*whs_pu)/D7 -> 6183.3274 | E10: =D10*(1+asp_g) -> 6306.994 | F10: =E10*(1+asp_g) -> 6433.1339 | G10: =F10*(1+asp_g) -> 6561.7965 | H10: =G10*(1+asp_g) -> 6693.0325 | I10: =H10*(1+asp_g) -> 6826.8931 | J10: =I10*(1+asp_g) -> 6963.431 | K10: =J10*(1+asp_g) -> 7102.6996 | L10: =K10*(1+asp_g) -> 7244.7536 | M10: =L10*(1+asp_g) -> 7389.6487
A11: 批發銷售與營收 | B11: US$M | C11: =C7*C10/1000000 -> 4052 | D11: =D7*D10/1000000 -> 5094.0459 | E11: =E7*E10/1000000 -> 6858.6234 | F11: =F7*F10/1000000 -> 8954.6187 | G11: =G7*G10/1000000 -> 11325.802 | H11: =H7*H10/1000000 -> 13862.781 | I11: =I7*I10/1000000 -> 16628.683 | J11: =J7*J10/1000000 -> 19539.368 | ... M11: =M7*M10/1000000 -> 22168.946
A12: 零售毛利／台 | B12: US$ | C12: =fy25_gp_ret*1000000/C7 -> 3315.2264 | D12: =(ytd_gp_ret*1000000+(D7-ytd_units)*(gpr_q4+q4_adj))/D7 -> 3303.3794 | E12: =gpr27_A -> 3600 | F12: =gpr27_A+(gprLT_A-gpr27_A)/3 -> 3633.3333 | G12: =gpr27_A+(gprLT_A-gpr27_A)*2/3 -> 3666.6667 | H12: =gprLT_A -> 3700 | I12: =gprLT_A -> 3700 | J12: =gprLT_A -> 3700 | K12: =gprLT_A -> 3700 | L12: =gprLT_A -> 3700 | M12: =gprLT_A -> 3700
A13: 批發毛利／零售台 | B13: US$ | C13: =fy25_gp_whs*1000000/C7 -> 806.17993 | D13: =(ytd_gp_whs*1000000+(D7-ytd_units)*gpw_h2)/D7 -> 753.775 | E13: =gpw_h2 -> 708 | F13: =gpw_h2 -> 708 | G13: =gpw_h2 -> 708 | H13: =gpw_h2 -> 708 | I13: =gpw_h2 -> 708 | J13: =gpw_h2 -> 708 | K13: =gpw_h2 -> 708 | L13: =gpw_h2 -> 708 | M13: =gpw_h2 -> 708
A14: 每零售台貸款發放額 | B14: US$ | C14: =fy25_orig*1000000/C7 -> 21465.169 | D14: =(ytd_orig*1000000+(D7-ytd_units)*opu)/D7 -> 23636.558 | E14: =D14*(1+asp_g) -> 24109.289 | F14: =E14*(1+asp_g) -> 24591.475 | G14: =F14*(1+asp_g) -> 25083.304 | H14: =G14*(1+asp_g) -> 25584.97 | I14: =H14*(1+asp_g) -> 26096.67 | J14: =I14*(1+asp_g) -> 26618.603 | K14: =J14*(1+asp_g) -> 27150.975 | L14: =K14*(1+asp_g) -> 27693.994 | M14: =L14*(1+asp_g) -> 28247.874
A15: 貸款發放 | B15: US$M | C15: =C7*C14/1000000 -> 12807 | D15: =D7*D14/1000000 -> 19472.64 | E15: =E7*E14/1000000 -> 26217.962 | F15: =F7*F14/1000000 -> 34230.172 | G15: =G7*G14/1000000 -> 43294.321 | H15: =H7*H14/1000000 -> 52992.249 | I15: =I7*I14/1000000 -> 63565.263 | J15: =J7*J14/1000000 -> 74691.727 | ... M15: =M7*M14/1000000 -> 84743.623
A16: 貸款出售利得率 | B16: % | C16: =fy25_gos/fy25_orig -> 0.093152182 | D16: =(ytd_gos+(D15-ytd_orig)*gos_h2)/D15 -> 0.075625082 | E16: =gos27_A -> 0.08 | F16: =gos27_A+(gosLT_A-gos27_A)/3 -> 0.08 | G16: =gos27_A+(gosLT_A-gos27_A)*2/3 -> 0.08 | H16: =gosLT_A -> 0.08 | I16: =gosLT_A -> 0.08 | J16: =gosLT_A -> 0.08 | K16: =gosLT_A -> 0.08 | L16: =gosLT_A -> 0.08 | M16: =gosLT_A -> 0.08
A17: 貸款出售利得（其他毛利之一） | B17: US$M | C17: =C15*C16 -> 1193 | D17: =D15*D16 -> 1472.62 | E17: =E15*E16 -> 2097.437 | F17: =F15*F16 -> 2738.4137 | G17: =G15*G16 -> 3463.5457 | H17: =H15*H16 -> 4239.3799 | I17: =I15*I16 -> 5085.221 | J17: =J15*J16 -> 5975.3381 | ... M17: =M15*M16 -> 6779.4898
A18: 非貸款其他毛利／台 | B18: US$ | C18: =(Q!M8-fy25_gos)*1000000/C7 -> 905.06687 | D18: =((Q!K8-ytd_gos)*1000000+(D7-ytd_units)*oth_pu)/D7 -> 945.89249 | E18: =D18*(1+oth_g) -> 945.89249 | F18: =E18*(1+oth_g) -> 945.89249 | G18: =F18*(1+oth_g) -> 945.89249 | H18: =G18*(1+oth_g) -> 945.89249 | I18: =H18*(1+oth_g) -> 945.89249 | J18: =I18*(1+oth_g) -> 945.89249 | K18: =J18*(1+oth_g) -> 945.89249 | L18: =K18*(1+oth_g) -> 945.89249 | M18: =L18*(1+oth_g) -> 945.89249
A19: 非貸款其他毛利（VSC、GAP 等） | B19: US$M | C19: =C7*C18/1000000 -> 540 | D19: =D7*D18/1000000 -> 779.26 | E19: =E7*E18/1000000 -> 1028.6232 | F19: =F7*F18/1000000 -> 1316.6377 | G19: =G7*G18/1000000 -> 1632.6307 | H19: =H7*H18/1000000 -> 1959.1569 | I19: =I7*I18/1000000 -> 2303.9685 | J19: =J7*J18/1000000 -> 2654.1717 | ... M19: =M7*M18/1000000 -> 2837.6775
A20: 零售毛利 | B20: US$M | C20: =C7*C12/1000000 -> 1978 | D20: =D7*D12/1000000 -> 2721.4419 | E20: =E7*E12/1000000 -> 3914.8672 | F20: =F7*F12/1000000 -> 5057.4285 | G20: =G7*G12/1000000 -> 6328.7454 | H20: =H7*H12/1000000 -> 7663.5353 | I20: =I7*I12/1000000 -> 9012.3175 | J20: =J7*J12/1000000 -> 10382.19 | ... M20: =M7*M12/1000000 -> 11100
A21: 批發毛利 | B21: US$M | C21: =C7*C13/1000000 -> 481 | D21: =D7*D13/1000000 -> 620.98675 | E21: =E7*E13/1000000 -> 769.92389 | F21: =F7*F13/1000000 -> 985.50258 | G21: =G7*G13/1000000 -> 1222.0232 | H21: =H7*H13/1000000 -> 1466.4278 | I21: =I7*I13/1000000 -> 1724.5191 | J21: =J7*J13/1000000 -> 1986.6461 | ... M21: =M7*M13/1000000 -> 2124
A22: 其他毛利（＝其他營收） | B22: US$M | C22: =C17+C19 -> 1733 | D22: =D17+D19 -> 2251.88 | E22: =E17+E19 -> 3126.0602 | F22: =F17+F19 -> 4055.0514 | G22: =G17+G19 -> 5096.1764 | H22: =H17+H19 -> 6198.5368 | I22: =I17+I19 -> 7389.1895 | J22: =J17+J19 -> 8629.5098 | ... M22: =M17+M19 -> 9617.1673
A23: 總毛利／台 | B23: US$ | C23: =(C20+C21+C22)*1000000/C7 -> 7026.0006 | D23: =(D20+D21+D22)*1000000/D7 -> 6790.5635 | E23: =(E20+E21+E22)*1000000/E7 -> 7182.6356 | F23: =(F20+F21+F22)*1000000/F7 -> 7254.5438 | G23: =(G20+G21+G22)*1000000/G7 -> 7327.2235 | H23: =(H20+H21+H22)*1000000/H7 -> 7400.6901 | I23: =(I20+I21+I22)*1000000/I7 -> 7441.6261 | J23: =(J20+J21+J22)*1000000/J7 -> 7483.3807 | ... M23: =(M20+M21+M22)*1000000/M7 -> 7613.7224
A24: SG&A | B24: US$M | C24: =Q!M12 -> 2308 | D24: =ytd_sga+sga_fix+(D7-ytd_units)*sga_var/1000000 -> 2989.8516 | E24: =4*sga_fix*(1+infl)^1+E7*sga_var*(1-eff_A)^1/1000000 -> 3653.9498 | F24: =4*sga_fix*(1+infl)^2+F7*sga_var*(1-eff_A)^2/1000000 -> 4388.5395 | G24: =4*sga_fix*(1+infl)^3+G7*sga_var*(1-eff_A)^3/1000000 -> 5153.8753 | H24: =4*sga_fix*(1+infl)^4+H7*sga_var*(1-eff_A)^4/1000000 -> 5899.5416 | I24: =4*sga_fix*(1+infl)^5+I7*sga_var*(1-eff_A)^5/1000000 -> 6644.9859 | J24: =4*sga_fix*(1+infl)^6+J7*sga_var*(1-eff_A)^6/1000000 -> 7356.4436 | K24: =4*sga_fix*(1+infl)^7+K7*sga_var*(1-eff_A)^7/1000000 -> 7623.3701 | L24: =4*sga_fix*(1+infl)^8+L7*sga_var*(1-eff_A)^8/1000000 -> 7444.8479 | M24: =4*sga_fix*(1+infl)^9+M7*sga_var*(1-eff_A)^9/1000000 -> 7273.1867
A25: SG&A／台 | B25: US$ | C25: =C24*1000000/C7 -> 3868.3228 | D25: =D24*1000000/D7 -> 3629.1843 | E25: =E24*1000000/E7 -> 3360.0678 | F25: =F24*1000000/F7 -> 3152.7933 | G25: =G24*1000000/G7 -> 2985.9856 | H25: =H24*1000000/H7 -> 2848.3334 | I25: =I24*1000000/I7 -> 2728.0938 | J25: =J24*1000000/J7 -> 2621.686 | ... M25: =M24*1000000/M7 -> 2424.3956
A26: 變動 SG&A／台 | B26: US$ | D26: =sga_var -> 2800 | E26: =sga_var*(1-eff_A)^1 -> 2716 | F26: =sga_var*(1-eff_A)^2 -> 2634.52 | G26: =sga_var*(1-eff_A)^3 -> 2555.4844 | H26: =sga_var*(1-eff_A)^4 -> 2478.8199 | I26: =sga_var*(1-eff_A)^5 -> 2404.4553 | J26: =sga_var*(1-eff_A)^6 -> 2332.3216 | K26: =sga_var*(1-eff_A)^7 -> 2262.352 | L26: =sga_var*(1-eff_A)^8 -> 2194.4814 | M26: =sga_var*(1-eff_A)^9 -> 2128.647
A27: 年產能（期末，足以支應次年台數） | B27: 輛 | D27: =MAX(cap_0,E7/util) -> 1500000 | E27: =MAX(D27,MIN(F7,unit_cap)/util) -> 1637591.5 | F27: =MAX(E27,MIN(G7,unit_cap)/util) -> 2030613.5 | G27: =MAX(F27,MIN(H7,unit_cap)/util) -> 2436736.2 | H27: =MAX(G27,MIN(I7,unit_cap)/util) -> 2865601.8 | I27: =MAX(H27,MIN(J7,unit_cap)/util) -> 3301173.2 | J27: =MAX(I27,MIN(K7,unit_cap)/util) -> 3529411.8 | K27: =MAX(J27,MIN(L7,unit_cap)/util) -> 3529411.8 | L27: =MAX(K27,MIN(M7,unit_cap)/util) -> 3529411.8 | M27: =MAX(L27,MIN(M7*(1+M6),unit_cap)/util) -> 3529411.8
A28: 成長性資本支出（新增產能 × 每台成本） | B28: US$M | D28: =0 -> 0 | E28: =(E27-D27)*capcost/1000000 -> 82.554917 | F28: =(F27-E27)*capcost/1000000 -> 235.81318 | G28: =(G27-F27)*capcost/1000000 -> 243.67362 | H28: =(H27-G27)*capcost/1000000 -> 257.31934 | I28: =(I27-H27)*capcost/1000000 -> 261.34288 | J28: =(J27-I27)*capcost/1000000 -> 136.94312 | K28: =(K27-J27)*capcost/1000000 -> 0 | L28: =(L27-K27)*capcost/1000000 -> 0 | M28: =(M27-L27)*capcost/1000000 -> 0
A31: 情境 B（基準：成長放緩、利得率小降）
A32: 項目 | B32: 單位 | C32: FY2025A | D32: FY2026E | E32: FY2027E | F32: FY2028E | G32: FY2029E | H32: FY2030E | I32: FY2031E | J32: FY2032E | K32: FY2033E | L32: FY2034E | M32: FY2035E
A33: 零售台數年增（2027 起為輸入；觸及上限後實際年增較低） | B33: % | C33: =Q!M4/Q!L4-1 -> 0.43303438 | D33: =D34/C34-1 -> 0.38078962 | E33: =g27_B -> 0.25 | F33: =g28_B -> 0.2 | G33: =(g28_B+g30_B)/2 -> 0.165 | H33: =g30_B -> 0.13 | I33: =g30_B+(g35_B-g30_B)*1/5 -> 0.114 | J33: =g30_B+(g35_B-g30_B)*2/5 -> 0.098 | K33: =g30_B+(g35_B-g30_B)*3/5 -> 0.082 | L33: =g30_B+(g35_B-g30_B)*4/5 -> 0.066 | M33: =g30_B+(g35_B-g30_B)*5/5 -> 0.05
A34: 零售台數 | B34: 輛 | C34: =fy25_units -> 596641 | D34: =ytd_units+u_q4 -> 823835.7 | E34: =MIN(D34*(1+E33),unit_cap) -> 1029794.6 | F34: =MIN(E34*(1+F33),unit_cap) -> 1235753.6 | G34: =MIN(F34*(1+G33),unit_cap) -> 1439652.9 | H34: =MIN(G34*(1+H33),unit_cap) -> 1626807.8 | I34: =MIN(H34*(1+I33),unit_cap) -> 1812263.8 | J34: =MIN(I34*(1+J33),unit_cap) -> 1989865.7 | K34: =MIN(J34*(1+K33),unit_cap) -> 2153034.7 | L34: =MIN(K34*(1+L33),unit_cap) -> 2295135 | M34: =MIN(L34*(1+M33),unit_cap) -> 2409891.7
A35: 零售每台營收 | B35: US$ | C35: =fy25_rev_ret*1000000/C34 -> 24364.735 | D35: =(ytd_rev_ret*1000000+(D34-ytd_units)*asp_q4)/D34 -> 27609.669 | E35: =D35*(1+asp_g) -> 28161.863 | F35: =E35*(1+asp_g) -> 28725.1 | G35: =F35*(1+asp_g) -> 29299.602 | H35: =G35*(1+asp_g) -> 29885.594 | I35: =H35*(1+asp_g) -> 30483.306 | J35: =I35*(1+asp_g) -> 31092.972 | K35: =J35*(1+asp_g) -> 31714.832 | L35: =K35*(1+asp_g) -> 32349.128 | M35: =L35*(1+asp_g) -> 32996.111
A36: 零售車輛銷售 | B36: US$M | C36: =C34*C35/1000000 -> 14537 | D36: =D34*D35/1000000 -> 22745.831 | E36: =E34*E35/1000000 -> 29000.935 | F36: =F34*F35/1000000 -> 35497.144 | G36: =G34*G35/1000000 -> 42181.257 | H36: =H34*H35/1000000 -> 48618.116 | I36: =I34*I35/1000000 -> 55243.793 | J36: =J34*J35/1000000 -> 61870.839 | ... M36: =M34*M35/1000000 -> 79517.054
A37: 批發營收／零售台 | B37: US$ | C37: =fy25_rev_whs*1000000/C34 -> 6791.3536 | D37: =(ytd_rev_whs*1000000+(D34-ytd_units)*whs_pu)/D34 -> 6183.3274 | E37: =D37*(1+asp_g) -> 6306.994 | F37: =E37*(1+asp_g) -> 6433.1339 | G37: =F37*(1+asp_g) -> 6561.7965 | H37: =G37*(1+asp_g) -> 6693.0325 | I37: =H37*(1+asp_g) -> 6826.8931 | J37: =I37*(1+asp_g) -> 6963.431 | K37: =J37*(1+asp_g) -> 7102.6996 | L37: =K37*(1+asp_g) -> 7244.7536 | M37: =L37*(1+asp_g) -> 7389.6487
A38: 批發銷售與營收 | B38: US$M | C38: =C34*C37/1000000 -> 4052 | D38: =D34*D37/1000000 -> 5094.0459 | E38: =E34*E37/1000000 -> 6494.9085 | F38: =F34*F37/1000000 -> 7949.768 | G38: =G34*G37/1000000 -> 9446.7093 | H38: =H34*H37/1000000 -> 10888.277 | I38: =I34*I37/1000000 -> 12372.132 | J38: =J34*J37/1000000 -> 13856.292 | ... M38: =M34*M37/1000000 -> 17808.253
A39: 零售毛利／台 | B39: US$ | C39: =fy25_gp_ret*1000000/C34 -> 3315.2264 | D39: =(ytd_gp_ret*1000000+(D34-ytd_units)*(gpr_q4+q4_adj))/D34 -> 3303.3794 | E39: =gpr27_B -> 3450 | F39: =gpr27_B+(gprLT_B-gpr27_B)/3 -> 3416.6667 | G39: =gpr27_B+(gprLT_B-gpr27_B)*2/3 -> 3383.3333 | H39: =gprLT_B -> 3350 | I39: =gprLT_B -> 3350 | J39: =gprLT_B -> 3350 | K39: =gprLT_B -> 3350 | L39: =gprLT_B -> 3350 | M39: =gprLT_B -> 3350
A40: 批發毛利／零售台 | B40: US$ | C40: =fy25_gp_whs*1000000/C34 -> 806.17993 | D40: =(ytd_gp_whs*1000000+(D34-ytd_units)*gpw_h2)/D34 -> 753.775 | E40: =gpw_h2 -> 708 | F40: =gpw_h2 -> 708 | G40: =gpw_h2 -> 708 | H40: =gpw_h2 -> 708 | I40: =gpw_h2 -> 708 | J40: =gpw_h2 -> 708 | K40: =gpw_h2 -> 708 | L40: =gpw_h2 -> 708 | M40: =gpw_h2 -> 708
A41: 每零售台貸款發放額 | B41: US$ | C41: =fy25_orig*1000000/C34 -> 21465.169 | D41: =(ytd_orig*1000000+(D34-ytd_units)*opu)/D34 -> 23636.558 | E41: =D41*(1+asp_g) -> 24109.289 | F41: =E41*(1+asp_g) -> 24591.475 | G41: =F41*(1+asp_g) -> 25083.304 | H41: =G41*(1+asp_g) -> 25584.97 | I41: =H41*(1+asp_g) -> 26096.67 | J41: =I41*(1+asp_g) -> 26618.603 | K41: =J41*(1+asp_g) -> 27150.975 | L41: =K41*(1+asp_g) -> 27693.994 | M41: =L41*(1+asp_g) -> 28247.874
A42: 貸款發放 | B42: US$M | C42: =C34*C41/1000000 -> 12807 | D42: =D34*D41/1000000 -> 19472.64 | E42: =E34*E41/1000000 -> 24827.616 | F42: =F34*F41/1000000 -> 30389.002 | G42: =G34*G41/1000000 -> 36111.251 | H42: =H34*H41/1000000 -> 41621.828 | I42: =I34*I41/1000000 -> 47294.051 | J42: =J34*J41/1000000 -> 52967.445 | ... M42: =M34*M41/1000000 -> 68074.319
A43: 貸款出售利得率 | B43: % | C43: =fy25_gos/fy25_orig -> 0.093152182 | D43: =(ytd_gos+(D42-ytd_orig)*gos_h2)/D42 -> 0.075625082 | E43: =gos27_B -> 0.072 | F43: =gos27_B+(gosLT_B-gos27_B)/3 -> 0.071333333 | G43: =gos27_B+(gosLT_B-gos27_B)*2/3 -> 0.070666667 | H43: =gosLT_B -> 0.07 | I43: =gosLT_B -> 0.07 | J43: =gosLT_B -> 0.07 | K43: =gosLT_B -> 0.07 | L43: =gosLT_B -> 0.07 | M43: =gosLT_B -> 0.07
...

Sheet PL
A1: PL — 損益表。Carvana 只有一個應報導部門（10-Q 附註 2：CODM 看合併淨利）；營收列採公司固定揭露的三條營收線，「其他銷售與營收」下拆命題子列（貸款出售利得／非貸款）
A2: FY2025A 為實績（含第四季釋放評價備抵的稅務利益 2,785 與 TRA 重估等其他費用 2,250）；FY2026E＝上半年實績＋下半年模型
A3: 項目 | B3: 單位 | C3: FY2025A | D3: FY2026E | E3: FY2027E | F3: FY2028E | G3: FY2029E | H3: FY2030E | I3: FY2031E | J3: FY2032E | K3: FY2033E | L3: FY2034E | M3: FY2035E
A4: 核對列（三情境合計絕對差，應為 0）
A5: 核對：營收線合計 − 合併營收 | C5: =ABS(C9+C10+C11-C14)+ABS(C38+C39+C40-C43)+ABS(C67+C68+C69-C72) -> 0 | D5: =ABS(D9+D10+D11-D14)+ABS(D38+D39+D40-D43)+ABS(D67+D68+D69-D72) -> 0 | E5: =ABS(E9+E10+E11-E14)+ABS(E38+E39+E40-E43)+ABS(E67+E68+E69-E72) -> 0 | F5: =ABS(F9+F10+F11-F14)+ABS(F38+F39+F40-F43)+ABS(F67+F68+F69-F72) -> 0 | G5: =ABS(G9+G10+G11-G14)+ABS(G38+G39+G40-G43)+ABS(G67+G68+G69-G72) -> 0 | H5: =ABS(H9+H10+H11-H14)+ABS(H38+H39+H40-H43)+ABS(H67+H68+H69-H72) -> 0 | I5: =ABS(I9+I10+I11-I14)+ABS(I38+I39+I40-I43)+ABS(I67+I68+I69-I72) -> 0 | J5: =ABS(J9+J10+J11-J14)+ABS(J38+J39+J40-J43)+ABS(J67+J68+J69-J72) -> 0 | ... M5: =ABS(M9+M10+M11-M14)+ABS(M38+M39+M40-M43)+ABS(M67+M68+M69-M72) -> 0
A6: 核對：其他營收子列合計 − 其他營收 | C6: =ABS(C12+C13-C11)+ABS(C41+C42-C40)+ABS(C70+C71-C69) -> 0 | D6: =ABS(D12+D13-D11)+ABS(D41+D42-D40)+ABS(D70+D71-D69) -> 0 | E6: =ABS(E12+E13-E11)+ABS(E41+E42-E40)+ABS(E70+E71-E69) -> 0 | F6: =ABS(F12+F13-F11)+ABS(F41+F42-F40)+ABS(F70+F71-F69) -> 0 | G6: =ABS(G12+G13-G11)+ABS(G41+G42-G40)+ABS(G70+G71-G69) -> 0 | H6: =ABS(H12+H13-H11)+ABS(H41+H42-H40)+ABS(H70+H71-H69) -> 0 | I6: =ABS(I12+I13-I11)+ABS(I41+I42-I40)+ABS(I70+I71-I69) -> 0 | J6: =ABS(J12+J13-J11)+ABS(J41+J42-J40)+ABS(J70+J71-J69) -> 0 | ... M6: =ABS(M12+M13-M11)+ABS(M41+M42-M40)+ABS(M70+M71-M69) -> 0
A8: 情境 A（樂觀：沿公司 300 萬台路徑、利得率維持）
A9: 零售車輛銷售 | B9: US$M | C9: =Thesis!C9 -> 14537 | D9: =Thesis!D9 -> 22745.831 | E9: =Thesis!E9 -> 30624.987 | F9: =Thesis!F9 -> 39983.983 | G9: =Thesis!G9 -> 50571.742 | H9: =Thesis!H9 -> 61899.812 | I9: =Thesis!I9 -> 74250.063 | J9: =Thesis!J9 -> 87246.794 | ... M9: =Thesis!M9 -> 98988.332
A10: 批發銷售與營收 | B10: US$M | C10: =Thesis!C11 -> 4052 | D10: =Thesis!D11 -> 5094.0459 | E10: =Thesis!E11 -> 6858.6234 | F10: =Thesis!F11 -> 8954.6187 | G10: =Thesis!G11 -> 11325.802 | H10: =Thesis!H11 -> 13862.781 | I10: =Thesis!I11 -> 16628.683 | J10: =Thesis!J11 -> 19539.368 | ... M10: =Thesis!M11 -> 22168.946
A11: 其他銷售與營收 | B11: US$M | C11: =Q!M8 -> 1733 | D11: =Thesis!D22 -> 2251.88 | E11: =Thesis!E22 -> 3126.0602 | F11: =Thesis!F22 -> 4055.0514 | G11: =Thesis!G22 -> 5096.1764 | H11: =Thesis!H22 -> 6198.5368 | I11: =Thesis!I22 -> 7389.1895 | J11: =Thesis!J22 -> 8629.5098 | K11: =Thesis!K22 -> 9353.9115 | ... M11: =Thesis!M22 -> 9617.1673
A12: 其中：貸款出售利得（命題子列） | B12: US$M | C12: =Thesis!C17 -> 1193 | D12: =Thesis!D17 -> 1472.62 | E12: =Thesis!E17 -> 2097.437 | F12: =Thesis!F17 -> 2738.4137 | G12: =Thesis!G17 -> 3463.5457 | H12: =Thesis!H17 -> 4239.3799 | I12: =Thesis!I17 -> 5085.221 | J12: =Thesis!J17 -> 5975.3381 | ... M12: =Thesis!M17 -> 6779.4898
A13: 其中：VSC、GAP 等非貸款（命題子列） | B13: US$M | C13: =C11-C12 -> 540 | D13: =D11-D12 -> 779.26 | E13: =E11-E12 -> 1028.6232 | F13: =F11-F12 -> 1316.6377 | G13: =G11-G12 -> 1632.6307 | H13: =H11-H12 -> 1959.1569 | I13: =I11-I12 -> 2303.9685 | J13: =J11-J12 -> 2654.1717 | ... M13: =M11-M12 -> 2837.6775
A14: 合併營收 | B14: US$M | C14: =Q!M9 -> 20322 | D14: =D9+D10+D11 -> 30091.757 | E14: =E9+E10+E11 -> 40609.671 | F14: =F9+F10+F11 -> 52993.654 | G14: =G9+G10+G11 -> 66993.72 | H14: =H9+H10+H11 -> 81961.131 | I14: =I9+I10+I11 -> 98267.936 | J14: =J9+J10+J11 -> 115415.67 | K14: =K9+K10+K11 -> 125806.5 | ... M14: =M9+M10+M11 -> 130774.45
A15: 營收年增 | B15: % | D15: =D14/C14-1 -> 0.48074782 | E15: =E14/D14-1 -> 0.34952806 | F15: =F14/E14-1 -> 0.30495156 | G15: =G14/F14-1 -> 0.26418384 | H15: =H14/G14-1 -> 0.22341512 | I15: =I14/H14-1 -> 0.19895779 | J15: =J14/I14-1 -> 0.17449981 | K15: =K14/J14-1 -> 0.090029652 | ... M15: =M14/L14-1 -> 0.019557532
A16: 零售毛利 | B16: US$M | C16: =Thesis!C20 -> 1978 | D16: =Thesis!D20 -> 2721.4419 | E16: =Thesis!E20 -> 3914.8672 | F16: =Thesis!F20 -> 5057.4285 | G16: =Thesis!G20 -> 6328.7454 | H16: =Thesis!H20 -> 7663.5353 | I16: =Thesis!I20 -> 9012.3175 | J16: =Thesis!J20 -> 10382.19 | ... M16: =Thesis!M20 -> 11100
A17: 批發毛利 | B17: US$M | C17: =Thesis!C21 -> 481 | D17: =Thesis!D21 -> 620.98675 | E17: =Thesis!E21 -> 769.92389 | F17: =Thesis!F21 -> 985.50258 | G17: =Thesis!G21 -> 1222.0232 | H17: =Thesis!H21 -> 1466.4278 | I17: =Thesis!I21 -> 1724.5191 | J17: =Thesis!J21 -> 1986.6461 | ... M17: =Thesis!M21 -> 2124
A18: 其他毛利 | B18: US$M | C18: =C11 -> 1733 | D18: =D11 -> 2251.88 | E18: =E11 -> 3126.0602 | F18: =F11 -> 4055.0514 | G18: =G11 -> 5096.1764 | H18: =H11 -> 6198.5368 | I18: =I11 -> 7389.1895 | J18: =J11 -> 8629.5098 | ... M18: =M11 -> 9617.1673
A19: 毛利合計 | B19: US$M | C19: =C16+C17+C18 -> 4192 | D19: =D16+D17+D18 -> 5594.3086 | E19: =E16+E17+E18 -> 7810.8513 | F19: =F16+F17+F18 -> 10097.983 | G19: =G16+G17+G18 -> 12646.945 | H19: =H16+H17+H18 -> 15328.5 | I19: =I16+I17+I18 -> 18126.026 | J19: =J16+J17+J18 -> 20998.346 | ... M19: =M16+M17+M18 -> 22841.167
A20: SG&A | B20: US$M | C20: =Thesis!C24 -> 2308 | D20: =Thesis!D24 -> 2989.8516 | E20: =Thesis!E24 -> 3653.9498 | F20: =Thesis!F24 -> 4388.5395 | G20: =Thesis!G24 -> 5153.8753 | H20: =Thesis!H24 -> 5899.5416 | I20: =Thesis!I24 -> 6644.9859 | J20: =Thesis!J24 -> 7356.4436 | ... M20: =Thesis!M24 -> 7273.1867
A21: 營業利益 | B21: US$M | C21: =fy25_oi -> 1881 | D21: =D19-D20 -> 2604.4571 | E21: =E19-E20 -> 4156.9015 | F21: =F19-F20 -> 5709.443 | G21: =G19-G20 -> 7493.0697 | H21: =H19-H20 -> 9428.9584 | I21: =I19-I20 -> 11481.04 | J21: =J19-J20 -> 13641.902 | K21: =K19-K20 -> 14954.541 | ... M21: =M19-M20 -> 15567.981
A22: 營業利益率 | B22: % | C22: =C21/C14 -> 0.092559787 | D22: =D21/D14 -> 0.086550514 | E22: =E21/E14 -> 0.10236235 | F22: =F21/F14 -> 0.10773824 | G22: =G21/G14 -> 0.11184734 | H22: =H21/H14 -> 0.11504183 | I22: =I21/I14 -> 0.11683404 | J22: =J21/J14 -> 0.118198 | ... M22: =M21/M14 -> 0.11904452
A23: 利息費用（淨；CF 頁債務表） | B23: US$M | C23: =fy25_int -> 505 | D23: =CF!D47 -> 390.40787 | E23: =CF!E47 -> 366.15625 | F23: =CF!F47 -> 344.03167 | G23: =CF!G47 -> 353.52801 | H23: =CF!H47 -> 401.82942 | I23: =CF!I47 -> 454.36382 | J23: =CF!J47 -> 512.22067 | K23: =CF!K47 -> 554.93371 | ... M23: =CF!M47 -> 484.86877
A24: 其他費用（收益） | B24: US$M | C24: =Q!M21 -> 2266 | D24: =ytd_oth_exp -> 105 | E24: =0 -> 0 | F24: =0 -> 0 | G24: =0 -> 0 | H24: =0 -> 0 | I24: =0 -> 0 | J24: =0 -> 0 | K24: =0 -> 0 | L24: =0 -> 0 | M24: =0 -> 0
A25: 稅前淨利 | B25: US$M | C25: =C21-C23-C24 -> -890 | D25: =D21-D23-D24 -> 2109.0492 | E25: =E21-E23-E24 -> 3790.7452 | F25: =F21-F23-F24 -> 5365.4114 | G25: =G21-G23-G24 -> 7139.5417 | H25: =H21-H23-H24 -> 9027.129 | I25: =I21-I23-I24 -> 11026.676 | J25: =J21-J23-J24 -> 13129.681 | ... M25: =M21-M23-M24 -> 15083.112
A26: 所得稅 | B26: US$M | C26: =fy25_tax -> -2785 | D26: =ytd_tax+(D25-(ytd_oi-ytd_int-ytd_oth_exp))*etr_26 -> 229.41947 | E26: =E25*etr_27 -> 454.88943 | F26: =F25*(etr_27+(etr_30-etr_27)/3) -> 751.15759 | G26: =G25*(etr_27+(etr_30-etr_27)*2/3) -> 1142.3267 | H26: =H25*etr_30 -> 1624.8832 | I26: =I25*etr_30 -> 1984.8018 | J26: =J25*etr_30 -> 2363.3427 | K26: =K25*etr_30 -> 2591.9294 | L26: =L25*etr_30 -> 2661.7372 | M26: =M25*etr_30 -> 2714.9601
A27: 淨利（合併，含非控制權益） | B27: US$M | C27: =C25-C26 -> 1895 | D27: =D25-D26 -> 1879.6297 | E27: =E25-E26 -> 3335.8558 | F27: =F25-F26 -> 4614.2538 | G27: =G25-G26 -> 5997.2151 | H27: =H25-H26 -> 7402.2458 | I27: =I25-I26 -> 9041.8747 | J27: =J25-J26 -> 10766.339 | ... M27: =M25-M26 -> 12368.152
A28: 淨利率 | B28: % | C28: =C27/C14 -> 0.093248696 | D28: =D27/D14 -> 0.062463275 | E28: =E27/E14 -> 0.08214437 | F28: =F27/F14 -> 0.087071818 | G28: =G27/G14 -> 0.089519063 | H28: =H27/H14 -> 0.090314101 | I28: =I27/I14 -> 0.092012462 | J28: =J27/J14 -> 0.093283162 | ... M28: =M27/M14 -> 0.094576213
A29: 每股盈餘（完全轉換股數） | B29: US$ | D29: =D27/sh_fx -> 1.667817 | E29: =E27/sh_fx -> 2.9599431 | F29: =F27/sh_fx -> 4.0942802 | G29: =G27/sh_fx -> 5.3213976 | H29: =H27/sh_fx -> 6.5680974 | I29: =I27/sh_fx -> 8.0229589 | J29: =J27/sh_fx -> 9.5530956 | K29: =K27/sh_fx -> 10.477088 | ... M29: =M27/sh_fx -> 10.974403
A30: 折舊攤銷 | B30: US$M | C30: =fy25_da -> 275 | D30: =ytd_da+da_q4 -> 266 | E30: =(ytd_da+da_q4)*(1+infl) -> 273.98 | F30: =(ytd_da+da_q4)*(1+infl)^2+SUM(Thesis!E28:E28)/life -> 287.70306 | G30: =(ytd_da+da_q4)*(1+infl)^3+SUM(Thesis!E28:F28)/life -> 311.88992 | H30: =(ytd_da+da_q4)*(1+infl)^4+SUM(Thesis!E28:G28)/life -> 336.85479 | I30: =(ytd_da+da_q4)*(1+infl)^5+SUM(Thesis!E28:H28)/life -> 362.99097 | J30: =(ytd_da+da_q4)*(1+infl)^6+SUM(Thesis!E28:I28)/life -> 389.66484 | K30: =(ytd_da+da_q4)*(1+infl)^7+SUM(Thesis!E28:J28)/life -> 408.32292 | L30: =(ytd_da+da_q4)*(1+infl)^8+SUM(Thesis!E28:K28)/life -> 418.13731 | M30: =(ytd_da+da_q4)*(1+infl)^9+SUM(Thesis!E28:L28)/life -> 428.24614
A31: 股份基礎給付 | B31: US$M | C31: =fy25_sbc -> 99 | D31: =ytd_sbc+sbc_q4 -> 103 | E31: =(ytd_sbc+sbc_q4)*(1+infl)^1 -> 106.09 | F31: =(ytd_sbc+sbc_q4)*(1+infl)^2 -> 109.2727 | G31: =(ytd_sbc+sbc_q4)*(1+infl)^3 -> 112.55088 | H31: =(ytd_sbc+sbc_q4)*(1+infl)^4 -> 115.92741 | I31: =(ytd_sbc+sbc_q4)*(1+infl)^5 -> 119.40523 | J31: =(ytd_sbc+sbc_q4)*(1+infl)^6 -> 122.98739 | K31: =(ytd_sbc+sbc_q4)*(1+infl)^7 -> 126.67701 | L31: =(ytd_sbc+sbc_q4)*(1+infl)^8 -> 130.47732 | M31: =(ytd_sbc+sbc_q4)*(1+infl)^9 -> 134.39164
A32: 權證營收（扣除） | B32: US$M | C32: =fy25_warrant -> 21 | D32: =ytd_warrant+warr/4 -> 21.25 | E32: =warr -> 21 | F32: =warr -> 21 | G32: =warr -> 21 | H32: =warr -> 21 | I32: =warr -> 21 | J32: =warr -> 21 | K32: =warr -> 21 | L32: =warr -> 21 | M32: =warr -> 21
A33: 調整後 EBITDA | B33: US$M | C33: =Q!M19 -> 2237 | D33: =D21+D30+D31-D32 -> 2952.2071 | E33: =E21+E30+E31-E32 -> 4515.9715 | F33: =F21+F30+F31-F32 -> 6085.4188 | G33: =G21+G30+G31-G32 -> 7896.5105 | H33: =H21+H30+H31-H32 -> 9860.7406 | I33: =I21+I30+I31-I32 -> 11942.436 | J33: =J21+J30+J31-J32 -> 14133.554 | K33: =K21+K30+K31-K32 -> 15468.541 | ... M33: =M21+M30+M31-M32 -> 16109.618
A34: 調整後 EBITDA 率 | B34: % | C34: =C33/C14 -> 0.11007775 | D34: =D33/D14 -> 0.098106835 | E34: =E33/E14 -> 0.11120434 | F34: =F33/F14 -> 0.11483297 | G34: =G33/G14 -> 0.11786941 | H34: =H33/H14 -> 0.12030996 | I34: =I33/I14 -> 0.12152933 | J34: =J33/J14 -> 0.12245784 | ... M34: =M33/M14 -> 0.12318629
A35: 貸款出售利得 ÷ 調整後 EBITDA | B35: % | C35: =C12/C33 -> 0.53330353 | D35: =D12/D33 -> 0.49882003 | E35: =E12/E33 -> 0.46444868 | F35: =F12/F33 -> 0.44999594 | G35: =G12/G33 -> 0.43861725 | H35: =H12/H33 -> 0.4299251 | I35: =I12/I33 -> 0.42581102 | J35: =J12/J33 -> 0.42277675 | ... M35: =M12/M33 -> 0.42083491
A37: 情境 B（基準：成長放緩、利得率小降）
A38: 零售車輛銷售 | B38: US$M | C38: =Thesis!C36 -> 14537 | D38: =Thesis!D36 -> 22745.831 | E38: =Thesis!E36 -> 29000.935 | F38: =Thesis!F36 -> 35497.144 | G38: =Thesis!G36 -> 42181.257 | H38: =Thesis!H36 -> 48618.116 | I38: =Thesis!I36 -> 55243.793 | J38: =Thesis!J36 -> 61870.839 | ... M38: =Thesis!M36 -> 79517.054
A39: 批發銷售與營收 | B39: US$M | C39: =Thesis!C38 -> 4052 | D39: =Thesis!D38 -> 5094.0459 | E39: =Thesis!E38 -> 6494.9085 | F39: =Thesis!F38 -> 7949.768 | G39: =Thesis!G38 -> 9446.7093 | H39: =Thesis!H38 -> 10888.277 | I39: =Thesis!I38 -> 12372.132 | J39: =Thesis!J38 -> 13856.292 | ... M39: =Thesis!M38 -> 17808.253
A40: 其他銷售與營收 | B40: US$M | C40: =Q!M8 -> 1733 | D40: =Thesis!D49 -> 2251.88 | E40: =Thesis!E49 -> 2761.6634 | F40: =Thesis!F49 -> 3336.6388 | G40: =Thesis!G49 -> 3913.6186 | H40: =Thesis!H49 -> 4452.3132 | I40: =Thesis!I49 -> 5024.7903 | J40: =Thesis!J49 -> 5589.9202 | K40: =Thesis!K49 -> 6128.5287 | ... M40: =Thesis!M49 -> 7044.7008
A41: 其中：貸款出售利得（命題子列） | B41: US$M | C41: =Thesis!C44 -> 1193 | D41: =Thesis!D44 -> 1472.62 | E41: =Thesis!E44 -> 1787.5884 | F41: =Thesis!F44 -> 2167.7488 | G41: =Thesis!G44 -> 2551.8617 | H41: =Thesis!H44 -> 2913.528 | I41: =Thesis!I44 -> 3310.5835 | J41: =Thesis!J44 -> 3707.7212 | ... M41: =Thesis!M44 -> 4765.2023
A42: 其中：VSC、GAP 等非貸款（命題子列） | B42: US$M | C42: =C40-C41 -> 540 | D42: =D40-D41 -> 779.26 | E42: =E40-E41 -> 974.075 | F42: =F40-F41 -> 1168.89 | G42: =G40-G41 -> 1361.7568 | H42: =H40-H41 -> 1538.7852 | I42: =I40-I41 -> 1714.2068 | J42: =J40-J41 -> 1882.199 | ... M42: =M40-M41 -> 2279.4985
...

Sheet CF
A1: CF — 收支模組。收支關卡＝自由現金流 − TRA 付款 − 代 NCI 繳稅 − 排定到期本金 − 贖回溢價；期末現金低於最低營運現金時以新增外部融資補足（利息自次年計）。FY2026＝全年（上半年實績＋下半年模型）
A2: 利息以期初餘額 × 各工具利率計（避免循環參照）；「其他利息與費用」以 Q2 2026 實績校準，並隨貸款發放量縮放
A3: 收支摘要 | B3: 單位 | C3: 情境 A | D3: 情境 B | E3: 情境 C
A4: 收支關卡：FY2027–FY2031 合計（A／B／C 於 C、D、E 欄） | C4: =SUM(E30:I30) -> 23175.187 | D4: =SUM(E68:I68) -> 16038.47 | E4: =SUM(E106:I106) -> 5947.1788
A5: 新增外部融資需求：FY2027–FY2031 合計 | C5: =SUM(E32:I32) -> 0 | D5: =SUM(E70:I70) -> 0 | E5: =SUM(E108:I108) -> 0
A6: FY2027–FY2031 期末現金最低值 | C6: =MIN(E34:I34) -> 5000 | D6: =MIN(E72:I72) -> 5000 | E6: =MIN(E110:I110) -> 4225.3682
A7: FY2027–FY2031 超額現金（高於現金上限，可回饋股東或提前還債）合計 | C7: =SUM(E33:I33) -> 22029.433 | D7: =SUM(E71:I71) -> 14892.716 | E7: =SUM(E109:I109) -> 4801.4242
A9: 其他利息與費用校準（年化，以 2026-09-30 結構；扣除 Q3 中 2030 年票據 1.5 個月的高利率） | B9: US$M | C9: =4*(int_lq-tlb*(ssn_r-swap_fix-tlb_sp)*1.5/12)-tlb*(swap_fix+tlb_sp)-ssn_31*ssn_r-uns*uns_r-re_fin*re_r-bi_adv*lq_bi*bi_r-fleet*fleet_r-finls*finls_r-fp_ratio*lq_inv*fp_r+lq_cash*cash_y -> 71.7616
A12: 情境 A（樂觀：沿公司 300 萬台路徑、利得率維持）
A13: 項目 | B13: 單位 | C13: FY2025A | D13: FY2026E | E13: FY2027E | F13: FY2028E | G13: FY2029E | H13: FY2030E | I13: FY2031E | J13: FY2032E | K13: FY2033E | L13: FY2034E | M13: FY2035E
A14: 存貨（期末） | B14: US$M | C14: =d25_inv -> 2408 | D14: =inv_d*(PL!D9-PL!D16)/365 -> 3291.6805 | E14: =inv_d*(PL!E9-PL!E16)/365 -> 4390.7047 | F14: =inv_d*(PL!F9-PL!F16)/365 -> 5741.3515 | G14: =inv_d*(PL!G9-PL!G16)/365 -> 7272.8214 | H14: =inv_d*(PL!H9-PL!H16)/365 -> 8915.5524 | I14: =inv_d*(PL!I9-PL!I16)/365 -> 10724.013 | J14: =inv_d*(PL!J9-PL!J16)/365 -> 12635.277 | K14: =inv_d*(PL!K9-PL!K16)/365 -> 13815.533 | ... M14: =inv_d*(PL!M9-PL!M16)/365 -> 14447.397
A15: 待售貸款（期末） | B15: US$M | C15: =d25_frhfs -> 813 | D15: =fr_d*Thesis!D15/365 -> 853.59518 | E15: =fr_d*Thesis!E15/365 -> 1149.2805 | F15: =fr_d*Thesis!F15/365 -> 1500.5007 | G15: =fr_d*Thesis!G15/365 -> 1897.8333 | H15: =fr_d*Thesis!H15/365 -> 2322.9479 | I15: =fr_d*Thesis!I15/365 -> 2786.4225 | J15: =fr_d*Thesis!J15/365 -> 3274.1579 | K15: =fr_d*Thesis!K15/365 -> 3570.5392 | ... M15: =fr_d*Thesis!M15/365 -> 3714.789
A16: 應付與應計（期末） | B16: US$M | C16: 1100 | D16: =ap_pct*(PL!D14-PL!D19+PL!D20) -> 1484.3142 | E16: =ap_pct*(PL!E14-PL!E19+PL!E20) -> 1968.4495 | F16: =ap_pct*(PL!F14-PL!F19+PL!F20) -> 2553.3474 | G16: =ap_pct*(PL!G14-PL!G19+PL!G20) -> 3213.0351 | H16: =ap_pct*(PL!H14-PL!H19+PL!H20) -> 3916.7373 | I16: =ap_pct*(PL!I14-PL!I19+PL!I20) -> 4686.4924 | J16: =ap_pct*(PL!J14-PL!J19+PL!J20) -> 5495.7836 | K16: =ap_pct*(PL!K14-PL!K19+PL!K20) -> 5986.006 | ... M16: =ap_pct*(PL!M14-PL!M19+PL!M20) -> 6221.1491
A17: 證券化受益權（期末，隨發放量縮放） | B17: US$M | C17: =d25_bi -> 486 | D17: =lq_bi*Thesis!D15/Thesis!D15 -> 557 | E17: =lq_bi*Thesis!E15/Thesis!D15 -> 749.9448 | F17: =lq_bi*Thesis!F15/Thesis!D15 -> 979.12793 | G17: =lq_bi*Thesis!G15/Thesis!D15 -> 1238.401 | H17: =lq_bi*Thesis!H15/Thesis!D15 -> 1515.8028 | I17: =lq_bi*Thesis!I15/Thesis!D15 -> 1818.2358 | J17: =lq_bi*Thesis!J15/Thesis!D15 -> 2136.4998 | K17: =lq_bi*Thesis!K15/Thesis!D15 -> 2329.8987 | L17: =lq_bi*Thesis!L15/Thesis!D15 -> 2376.4967 | M17: =lq_bi*Thesis!M15/Thesis!D15 -> 2424.0266
A18: 淨利 | B18: US$M | D18: =PL!D27 -> 1879.6297 | E18: =PL!E27 -> 3335.8558 | F18: =PL!F27 -> 4614.2538 | G18: =PL!G27 -> 5997.2151 | H18: =PL!H27 -> 7402.2458 | I18: =PL!I27 -> 9041.8747 | J18: =PL!J27 -> 10766.339 | K18: =PL!K27 -> 11807.678 | ... M18: =PL!M27 -> 12368.152
A19: ＋折舊攤銷＋SBC | B19: US$M | D19: =PL!D30+PL!D31 -> 369 | E19: =PL!E30+PL!E31 -> 380.07 | F19: =PL!F30+PL!F31 -> 396.97576 | G19: =PL!G30+PL!G31 -> 424.4408 | H19: =PL!H30+PL!H31 -> 452.7822 | I19: =PL!I30+PL!I31 -> 482.3962 | J19: =PL!J30+PL!J31 -> 512.65223 | K19: =PL!K30+PL!K31 -> 534.99993 | ... M19: =PL!M30+PL!M31 -> 562.63778
A20: ＋帳面稅與現金稅差額（遞延所得稅資產抵用） | B20: US$M | D20: =PL!D26-MAX(0,PL!D25)*ctr -> 166.148 | E20: =PL!E26-MAX(0,PL!E25)*ctr -> 341.16707 | F20: =PL!F26-MAX(0,PL!F25)*ctr -> 590.19525 | G20: =0 -> 0 | H20: =0 -> 0 | I20: =0 -> 0 | J20: =0 -> 0 | K20: =0 -> 0 | L20: =0 -> 0 | M20: =0 -> 0
A21: −營運資金增加（存貨＋待售貸款 − 應付） | B21: US$M | D21: =-((D14-C14)+(D15-C15)-(D16-C16)) -> -539.96143 | E21: =-((E14-D14)+(E15-D15)-(E16-D16)) -> -910.57424 | F21: =-((F14-E14)+(F15-E15)-(F16-E16)) -> -1116.9691 | G21: =-((G14-F14)+(G15-F15)-(G16-F16)) -> -1269.1147 | H21: =-((H14-G14)+(H15-G15)-(H16-G16)) -> -1364.1435 | I21: =-((I14-H14)+(I15-H15)-(I16-H16)) -> -1502.18 | J21: =-((J14-I14)+(J15-I15)-(J16-I16)) -> -1589.7086 | K21: =-((K14-J14)+(K15-J15)-(K16-J16)) -> -986.41479 | ... M21: =-((M14-L14)+(M15-L15)-(M16-L16)) -> -272.88442
A22: −風險自留淨現金（受益權增加 ×（1 − 融資成數）） | B22: US$M | D22: =-(D17-C17)*(1-bi_adv) -> -16.570916 | E22: =-(E17-D17)*(1-bi_adv) -> -45.032 | F22: =-(F17-E17)*(1-bi_adv) -> -53.489779 | G22: =-(G17-F17)*(1-bi_adv) -> -60.512567 | H22: =-(H17-G17)*(1-bi_adv) -> -64.743694 | I22: =-(I17-H17)*(1-bi_adv) -> -70.585795 | J22: =-(J17-I17)*(1-bi_adv) -> -74.280646 | K22: =-(K17-J17)*(1-bi_adv) -> -45.137988 | ... M22: =-(M17-L17)*(1-bi_adv) -> -11.093162
A23: 營業現金流（模型口徑） | B23: US$M | D23: =D18+D19+D20+D21+D22 -> 1858.2454 | E23: =E18+E19+E20+E21+E22 -> 3101.4867 | F23: =F18+F19+F20+F21+F22 -> 4430.9659 | G23: =G18+G19+G20+G21+G22 -> 5092.0286 | H23: =H18+H19+H20+H21+H22 -> 6426.1408 | I23: =I18+I19+I20+I21+I22 -> 7951.5051 | J23: =J18+J19+J20+J21+J22 -> 9615.0017 | K23: =K18+K19+K20+K21+K22 -> 11311.125 | ... M23: =M18+M19+M20+M21+M22 -> 12646.812
A24: 資本支出（維護＋成長） | B24: US$M | D24: =ytd_capex+capex_q4 -> 236 | E24: =PL!E14*mcx+Thesis!E28 -> 285.60327 | F24: =PL!F14*mcx+Thesis!F28 -> 500.78145 | G24: =PL!G14*mcx+Thesis!G28 -> 578.64222 | H24: =PL!H14*mcx+Thesis!H28 -> 667.12499 | I24: =PL!I14*mcx+Thesis!I28 -> 752.68256 | J24: =PL!J14*mcx+Thesis!J28 -> 714.02148 | K24: =PL!K14*mcx+Thesis!K28 -> 629.03252 | L24: =PL!L14*mcx+Thesis!L28 -> 641.32941 | M24: =PL!M14*mcx+Thesis!M28 -> 653.87223
A25: 自由現金流 | B25: US$M | D25: =D23-D24 -> 1622.2454 | E25: =E23-E24 -> 2815.8834 | F25: =F23-F24 -> 3930.1844 | G25: =G23-G24 -> 4513.3864 | H25: =H23-H24 -> 5759.0158 | I25: =I23-I24 -> 7198.8225 | J25: =J23-J24 -> 8900.9803 | K25: =K23-K24 -> 10682.093 | ... M25: =M23-M24 -> 11992.94
A26: TRA 付款 | B26: US$M | D26: =37+tra_q4 -> 37 | E26: =MIN(tra_0-tra_q4,tra_0/tra_yrs) -> 142 | F26: =MIN(tra_0-tra_q4-SUM(E26:E26),tra_0/tra_yrs) -> 142 | G26: =MIN(tra_0-tra_q4-SUM(E26:F26),tra_0/tra_yrs) -> 142 | H26: =MIN(tra_0-tra_q4-SUM(E26:G26),tra_0/tra_yrs) -> 142 | I26: =MIN(tra_0-tra_q4-SUM(E26:H26),tra_0/tra_yrs) -> 142 | J26: =MIN(tra_0-tra_q4-SUM(E26:I26),tra_0/tra_yrs) -> 142 | K26: =MIN(tra_0-tra_q4-SUM(E26:J26),tra_0/tra_yrs) -> 142 | L26: =MIN(tra_0-tra_q4-SUM(E26:K26),tra_0/tra_yrs) -> 142 | M26: =MIN(tra_0-tra_q4-SUM(E26:L26),tra_0/tra_yrs) -> 142
A27: 代非控制權益繳稅 | B27: US$M | D27: =ncitax -> 8 | E27: =ncitax -> 8 | F27: =ncitax -> 8 | G27: =ncitax -> 8 | H27: =ncitax -> 8 | I27: =ncitax -> 8 | J27: =ncitax -> 8 | K27: =ncitax -> 8 | ... M27: =ncitax -> 8
A28: 排定到期本金（定期貸款攤還、無擔保票據） | B28: US$M | D28: =0 -> 0 | E28: =tlb*0.01+32 -> 48.6 | F28: =tlb*0.01+22 -> 38.6 | G28: =tlb*0.01+26 -> 42.6 | H28: =tlb*0.01+27 -> 43.6 | I28: =tlb*0.01 -> 16.6 | J28: =tlb*0.01 -> 16.6 | K28: =tlb-tlb*0.01*6 -> 1560.4 | L28: =0 -> 0 | M28: =0 -> 0
A29: 贖回溢價與費用 | B29: US$M | D29: =redeem_cost -> 50 | E29: =IF(2027=refi_yr,ssn_31*refi_prem,0) -> 0 | F29: =IF(2028=refi_yr,ssn_31*refi_prem,0) -> 102.105 | G29: =IF(2029=refi_yr,ssn_31*refi_prem,0) -> 0 | H29: =IF(2030=refi_yr,ssn_31*refi_prem,0) -> 0 | I29: =IF(2031=refi_yr,ssn_31*refi_prem,0) -> 0 | J29: =IF(2032=refi_yr,ssn_31*refi_prem,0) -> 0 | K29: =IF(2033=refi_yr,ssn_31*refi_prem,0) -> 0 | L29: =IF(2034=refi_yr,ssn_31*refi_prem,0) -> 0 | M29: =IF(2035=refi_yr,ssn_31*refi_prem,0) -> 0
A30: 收支關卡：自由現金流扣 TRA 與到期本金 | B30: US$M | D30: =D25-D26-D27-D28-D29 -> 1527.2454 | E30: =E25-E26-E27-E28-E29 -> 2617.2834 | F30: =F25-F26-F27-F28-F29 -> 3639.4794 | G30: =G25-G26-G27-G28-G29 -> 4320.7864 | H30: =H25-H26-H27-H28-H29 -> 5565.4158 | I30: =I25-I26-I27-I28-I29 -> 7032.2225 | J30: =J25-J26-J27-J28-J29 -> 8734.3803 | K30: =K25-K26-K27-K28-K29 -> 8971.6929 | ... M30: =M25-M26-M27-M28-M29 -> 11842.94
A31: 期末現金（融資與分配前） | B31: US$M | D31: =C34+D30 -> 3854.2454 | E31: =D34+E30 -> 6471.5287 | F31: =E34+F30 -> 8639.4794 | G31: =F34+G30 -> 9320.7864 | H31: =G34+H30 -> 10565.416 | I31: =H34+I30 -> 12032.222 | J31: =I34+J30 -> 13734.38 | K31: =J34+K30 -> 13971.693 | ... M31: =L34+M30 -> 16842.94
A32: 新增外部融資（補足至最低營運現金） | B32: US$M | D32: =MAX(0,min_cash-D31) -> 0 | E32: =MAX(0,min_cash-E31) -> 0 | F32: =MAX(0,min_cash-F31) -> 0 | G32: =MAX(0,min_cash-G31) -> 0 | H32: =MAX(0,min_cash-H31) -> 0 | I32: =MAX(0,min_cash-I31) -> 0 | J32: =MAX(0,min_cash-J31) -> 0 | K32: =MAX(0,min_cash-K31) -> 0 | ... M32: =MAX(0,min_cash-M31) -> 0
A33: 超額現金（高於現金上限；視為回饋股東或提前還債，不再計息） | B33: US$M | D33: =MAX(0,D31-cash_cap) -> 0 | E33: =MAX(0,E31-cash_cap) -> 1471.5287 | F33: =MAX(0,F31-cash_cap) -> 3639.4794 | G33: =MAX(0,G31-cash_cap) -> 4320.7864 | H33: =MAX(0,H31-cash_cap) -> 5565.4158 | I33: =MAX(0,I31-cash_cap) -> 7032.2225 | J33: =MAX(0,J31-cash_cap) -> 8734.3803 | K33: =MAX(0,K31-cash_cap) -> 8971.6929 | ... M33: =MAX(0,M31-cash_cap) -> 11842.94
A34: 期末現金 | B34: US$M | C34: =d25_cash -> 2327 | D34: =D31+D32-D33 -> 3854.2454 | E34: =E31+E32-E33 -> 5000 | F34: =F31+F32-F33 -> 5000 | G34: =G31+G32-G33 -> 5000 | H34: =H31+H32-H33 -> 5000 | I34: =I31+I32-I33 -> 5000 | J34: =J31+J32-J33 -> 5000 | K34: =K31+K32-K33 -> 5000 | ... M34: =M31+M32-M33 -> 5000
A35: 債務（期末）
A36: 定期貸款 B（2026 年起；取代 2030 年擔保票據） | B36: US$M | C36: =0 -> 0 | D36: =tlb -> 1660 | E36: =tlb-tlb*0.01*1 -> 1643.4 | F36: =tlb-tlb*0.01*2 -> 1626.8 | G36: =tlb-tlb*0.01*3 -> 1610.2 | H36: =tlb-tlb*0.01*4 -> 1593.6 | I36: =tlb-tlb*0.01*5 -> 1577 | J36: =tlb-tlb*0.01*6 -> 1560.4 | K36: =0 -> 0 | L36: =0 -> 0 | M36: =0 -> 0
A37: 2030 年擔保票據 | B37: US$M | C37: =tlb_old -> 1660 | D37: =0 -> 0 | E37: =0 -> 0 | F37: =0 -> 0 | G37: =0 -> 0 | H37: =0 -> 0 | I37: =0 -> 0 | J37: =0 -> 0 | K37: =0 -> 0 | ... M37: =0 -> 0
A38: 2031 年擔保票據 | B38: US$M | C38: =IF(2025<refi_yr,ssn_31,0) -> 2269 | D38: =IF(2026<refi_yr,ssn_31,0) -> 2269 | E38: =IF(2027<refi_yr,ssn_31,0) -> 2269 | F38: =IF(2028<refi_yr,ssn_31,0) -> 0 | G38: =IF(2029<refi_yr,ssn_31,0) -> 0 | H38: =IF(2030<refi_yr,ssn_31,0) -> 0 | I38: =IF(2031<refi_yr,ssn_31,0) -> 0 | J38: =IF(2032<refi_yr,ssn_31,0) -> 0 | K38: =IF(2033<refi_yr,ssn_31,0) -> 0 | L38: =IF(2034<refi_yr,ssn_31,0) -> 0 | M38: =IF(2035<refi_yr,ssn_31,0) -> 0
A39: 2031 年票據再融資貸款 | B39: US$M | C39: =IF(2025>=refi_yr,ssn_31*(1+0),0) -> 0 | D39: =IF(2026>=refi_yr,ssn_31*(1+0),0) -> 0 | E39: =IF(2027>=refi_yr,ssn_31*(1+0),0) -> 0 | F39: =IF(2028>=refi_yr,ssn_31*(1+0),0) -> 2269 | G39: =IF(2029>=refi_yr,ssn_31*(1+0),0) -> 2269 | H39: =IF(2030>=refi_yr,ssn_31*(1+0),0) -> 2269 | I39: =IF(2031>=refi_yr,ssn_31*(1+0),0) -> 2269 | J39: =IF(2032>=refi_yr,ssn_31*(1+0),0) -> 2269 | K39: =IF(2033>=refi_yr,ssn_31*(1+0),0) -> 2269 | L39: =IF(2034>=refi_yr,ssn_31*(1+0),0) -> 2269 | M39: =IF(2035>=refi_yr,ssn_31*(1+0),0) -> 2269
A40: 無擔保票據 | B40: US$M | C40: =uns -> 107 | D40: =uns -> 107 | E40: =uns-32 -> 75 | F40: =uns-32-22 -> 53 | G40: =uns-32-22-26 -> 27 | H40: =0 -> 0 | I40: =0 -> 0 | J40: =0 -> 0 | K40: =0 -> 0 | L40: =0 -> 0 | M40: =0 -> 0
A41: 不動產售後租回融資 | B41: US$M | C41: =re_fin -> 485 | D41: =re_fin -> 485 | E41: =re_fin -> 485 | F41: =re_fin -> 485 | G41: =re_fin -> 485 | H41: =re_fin -> 485 | I41: =re_fin -> 485 | J41: =re_fin -> 485 | ... M41: =re_fin -> 485
A42: 受益權融資 | B42: US$M | C42: =bi_adv*C17 -> 372.57092 | D42: =bi_adv*D17 -> 427 | E42: =bi_adv*E17 -> 574.9128 | F42: =bi_adv*F17 -> 750.60615 | G42: =bi_adv*G17 -> 949.36666 | H42: =bi_adv*H17 -> 1162.0248 | I42: =bi_adv*I17 -> 1393.872 | J42: =bi_adv*J17 -> 1637.8553 | ... M42: =bi_adv*M17 -> 1858.2754
A43: 車隊融資＋融資租賃 | B43: US$M | C43: =fleet+finls -> 260 | D43: =fleet+finls -> 260 | E43: =fleet+finls -> 260 | F43: =fleet+finls -> 260 | G43: =fleet+finls -> 260 | H43: =fleet+finls -> 260 | I43: =fleet+finls -> 260 | J43: =fleet+finls -> 260 | ... M43: =fleet+finls -> 260
...

Sheet Credit
A1: Credit — 信用風險六個角度：(1) 公司債信指標（三情境逐年）(2) 消費信用（管理組合）(3) 出售利得對損失與利差的敏感度 (4) 貸款去化與資金斷點 (5) 盈餘品質與關係人 (6) 清償順位與資產覆蓋；另附壓力格
A2: 評等門檻為 Moody's（2025-10）與 S&P（2025-03）公開說法；2026 年評等動作未找到。所有比率以調整後 EBITDA（公司口徑）計，另列扣除貸款出售利得的版本
A3: 項目 | B3: 單位 | C3: FY2025A | D3: FY2026E | E3: FY2027E | F3: FY2028E | G3: FY2029E | H3: FY2030E | I3: FY2031E | J3: FY2032E | K3: FY2033E | L3: FY2034E | M3: FY2035E
A5: (1) 公司債信指標｜情境 A（樂觀：沿公司 300 萬台路徑、利得率維持）
A6: 債務合計 | B6: US$M | D6: =CF!D46 -> 5275.6242 | E6: =CF!E46 -> 5397.5154 | F6: =CF!F46 -> 5562.3564 | G6: =CF!G46 -> 5749.9794 | H6: =CF!H46 -> 5952.7857 | I6: =CF!I46 -> 6205.1859 | J6: =CF!J46 -> 6471.8342 | K6: =CF!K46 -> 5083.9423 | ... M6: =CF!M46 -> 5169.0824
A7: 現金 | B7: US$M | D7: =CF!D34 -> 3854.2454 | E7: =CF!E34 -> 5000 | F7: =CF!F34 -> 5000 | G7: =CF!G34 -> 5000 | H7: =CF!H34 -> 5000 | I7: =CF!I34 -> 5000 | J7: =CF!J34 -> 5000 | K7: =CF!K34 -> 5000 | ... M7: =CF!M34 -> 5000
A8: TRA 餘額（期末） | B8: US$M | D8: =tra_0-tra_q4 -> 2130 | E8: =tra_0-tra_q4-SUM(CF!E26:E26) -> 1988 | F8: =tra_0-tra_q4-SUM(CF!E26:F26) -> 1846 | G8: =tra_0-tra_q4-SUM(CF!E26:G26) -> 1704 | H8: =tra_0-tra_q4-SUM(CF!E26:H26) -> 1562 | I8: =tra_0-tra_q4-SUM(CF!E26:I26) -> 1420 | J8: =tra_0-tra_q4-SUM(CF!E26:J26) -> 1278 | K8: =tra_0-tra_q4-SUM(CF!E26:K26) -> 1136 | L8: =tra_0-tra_q4-SUM(CF!E26:L26) -> 994 | M8: =tra_0-tra_q4-SUM(CF!E26:M26) -> 852
A9: 調整後 EBITDA | B9: US$M | D9: =PL!D33 -> 2952.2071 | E9: =PL!E33 -> 4515.9715 | F9: =PL!F33 -> 6085.4188 | G9: =PL!G33 -> 7896.5105 | H9: =PL!H33 -> 9860.7406 | I9: =PL!I33 -> 11942.436 | J9: =PL!J33 -> 14133.554 | K9: =PL!K33 -> 15468.541 | ... M9: =PL!M33 -> 16109.618
A10: 調整後 EBITDA 扣除貸款出售利得 | B10: US$M | D10: =D9-Thesis!D17 -> 1479.5871 | E10: =E9-Thesis!E17 -> 2418.5345 | F10: =F9-Thesis!F17 -> 3347.0051 | G10: =G9-Thesis!G17 -> 4432.9648 | H10: =H9-Thesis!H17 -> 5621.3607 | I10: =I9-Thesis!I17 -> 6857.2154 | J10: =J9-Thesis!J17 -> 8158.2162 | K10: =K9-Thesis!K17 -> 8952.3073 | ... M10: =M9-Thesis!M17 -> 9330.1286
A11: 債務／EBITDA | B11: x | D11: =D6/D9 -> 1.7870102 | E11: =E6/E9 -> 1.1952058 | F11: =F6/F9 -> 0.9140466 | G11: =G6/G9 -> 0.72816712 | H11: =H6/H9 -> 0.60368546 | I11: =I6/I9 -> 0.51959128 | J11: =J6/J9 -> 0.45790564 | K11: =K6/K9 -> 0.32866333 | ... M11: =M6/M9 -> 0.32086933
A12: 淨債務／EBITDA | B12: x | D12: =(D6-D7)/D9 -> 0.48146313 | E12: =(E6-E7)/E9 -> 0.088024328 | F12: =(F6-F7)/F9 -> 0.092410463 | G12: =(G6-G7)/G9 -> 0.094976049 | H12: =(H6-H7)/H9 -> 0.096624155 | I12: =(I6-I7)/I9 -> 0.10091625 | J12: =(J6-J7)/J9 -> 0.10413759 | K12: =(K6-K7)/K9 -> 0.0054266476 | ... M12: =(M6-M7)/M9 -> 0.010495743
A13: 債務／扣除出售利得的 EBITDA | B13: x | D13: =IF(D10>0,D6/D10,"EBITDA≤0") -> 3.5656058 | E13: =IF(E10>0,E6/E10,"EBITDA≤0") -> 2.2317297 | F13: =IF(F10>0,F6/F10,"EBITDA≤0") -> 1.6618906 | G13: =IF(G10>0,G6/G10,"EBITDA≤0") -> 1.2970956 | H13: =IF(H10>0,H6/H10,"EBITDA≤0") -> 1.0589582 | I13: =IF(I10>0,I6/I10,"EBITDA≤0") -> 0.90491336 | J13: =IF(J10>0,J6/J10,"EBITDA≤0") -> 0.79329035 | K13: =IF(K10>0,K6/K10,"EBITDA≤0") -> 0.56789185 | ... M13: =IF(M10>0,M6/M10,"EBITDA≤0") -> 0.55402049
A14: （債務＋TRA）／EBITDA | B14: x | D14: =(D6+D8)/D9 -> 2.5085043 | E14: =(E6+E8)/E9 -> 1.6354212 | F14: =(F6+F8)/F9 -> 1.2173947 | G14: =(G6+G8)/G9 -> 0.94395864 | H14: =(H6+H8)/H9 -> 0.76209141 | I14: =(I6+I8)/I9 -> 0.63849499 | J14: =(J6+J8)/J9 -> 0.54832875 | K14: =(K6+K8)/K9 -> 0.40210271 | ... M14: =(M6+M8)/M9 -> 0.37375699
A15: （EBITDA − 資本支出）／利息（利息為淨收入時標示） | B15: x | D15: =IF(CF!D47<=0,"淨利息收入",(D9-CF!D24)/CF!D47) -> 6.9573572 | E15: =IF(CF!E47<=0,"淨利息收入",(E9-CF!E24)/CF!E47) -> 11.553451 | F15: =IF(CF!F47<=0,"淨利息收入",(F9-CF!F24)/CF!F47) -> 16.232917 | G15: =IF(CF!G47<=0,"淨利息收入",(G9-CF!G24)/CF!G47) -> 20.699543 | H15: =IF(CF!H47<=0,"淨利息收入",(H9-CF!H24)/CF!H47) -> 22.879399 | I15: =IF(CF!I47<=0,"淨利息收入",(I9-CF!I24)/CF!I47) -> 24.6273 | J15: =IF(CF!J47<=0,"淨利息收入",(J9-CF!J24)/CF!J47) -> 26.198734 | K15: =IF(CF!K47<=0,"淨利息收入",(K9-CF!K24)/CF!K47) -> 26.741047 | ... M15: =IF(CF!M47<=0,"淨利息收入",(M9-CF!M24)/CF!M47) -> 31.876143
